Workbook

Sheet 1. Exec One-Pager
B2: IF I AWAKEN IN LOS ANGELES
B3: Immersive theatre · 30,100 sq ft · 150-cap · 60-week Los Angeles run
B5: THE ASK | E5: KEY METRICS
B6: ='Production Budget'!F263 -> 6047850.3 | E6: Weekly Ticket Gross (100%) | F6: ='Seating Plan'!F26 -> 163000
E7: Weekly Operating Cost | F7: ='Weekly Operating'!F124 -> 135757
E8: Weekly Contribution @ 100% (incl F&B) | F8: ='Seating Plan'!F26+'Seating Plan'!G57-'Weekly Operating'!F124 -> 44073
B9: Total Capitalization Required | E9: Breakeven Capacity | F9: =Recoupment!C28 -> 0.74806791
E10: Avg Ticket Price (weighted) | F10: ='Seating Plan'!F26/'Seating Plan'!C9 -> 90.555556
B12: CAPITALIZATION BREAKDOWN | E12: WEEKLY OPERATING COSTS
B13: Scenic / Physical Production | C13: ='Production Budget'!F40 -> 2314250 | E13: Physical Maintenance | F13: ='Weekly Operating'!F21 -> 9300
B14: Creative & Management Fees | C14: ='Production Budget'!F90 -> 1008879 | E14: Fees (GM, PR, Marketing, Legal) | F14: ='Weekly Operating'!F37 -> 8400
B15: Pre-Opening Salaries | C15: ='Production Budget'!F135 -> 394919.48 | E15: Weekly Salaries (all staff) | F15: ='Weekly Operating'!F84 -> 81007
B16: Casting & Rehearsal | C16: ='Production Budget'!F150 -> 53500 | E16: Weekly Advertising | F16: ='Weekly Operating'!F97 -> 25500
B17: Music | C17: ='Production Budget'!F166 -> 51400 | E17: Venue & Tech (rent, utilities, CC) | F17: ='Weekly Operating'!F110 -> 8400
B18: Advertising & Launch | C18: ='Production Budget'!F187 -> 775500 | E18: General & Administrative | F18: ='Weekly Operating'!F122 -> 3150
B19: Venue Load-In & Tech Labor | C19: ='Production Budget'!F210 -> 190793.6
B20: General & Administrative | C20: ='Production Budget'!F225 -> 174700
B21: Developmental | C21: ='Production Budget'!F233 -> 75000 | E21: TOTAL WEEKLY OPERATING | F21: ='Weekly Operating'!F124 -> 135757
B22: Subtotal: Production Costs | C22: ='Production Budget'!F235 -> 5038942.1
B23: Bonds, Deposits, Advances | C23: ='Production Budget'!F252 -> 233500
B24: Reserve & 10% Contingency | C24: ='Production Budget'!F261 -> 775408.21
B25: TOTAL CAPITALIZATION | C25: ='Production Budget'!F263 -> 6047850.3
B27: RECOUPMENT AT CAPACITY SCENARIOS
B28: Capacity | C28: 100% | D28: 90% | E28: 80% | F28: 75%
B29: Weekly Contribution | C29: =('Seating Plan'!F26*1+'Seating Plan'!G57*1)-(('Weekly Operating'!F124-0.03*'Seating Plan'!F26)+0.03*1*'Seating Plan'!F26) -> 44073 | D29: =('Seating Plan'!F26*0.9+'Seating Plan'!G57*0.9)-(('Weekly Operating'!F124-0.03*'Seating Plan'!F26)+0.03*0.9*'Seating Plan'!F26) -> 26579 | E29: =('Seating Plan'!F26*0.8+'Seating Plan'!G57*0.8)-(('Weekly Operating'!F124-0.03*'Seating Plan'!F26)+0.03*0.8*'Seating Plan'!F26) -> 9085 | F29: =('Seating Plan'!F26*0.75+'Seating Plan'!G57*0.75)-(('Weekly Operating'!F124-0.03*'Seating Plan'!F26)+0.03*0.75*'Seating Plan'!F26) -> 338
B30: Weeks to Recoup | C30: =IF(('Seating Plan'!F26*1+'Seating Plan'!G57*1)-(('Weekly Operating'!F124-0.03*'Seating Plan'!F26)+0.03*1*'Seating Plan'!F26)>0,'Production Budget'!F263/(('Seating Plan'!F26*1+'Seating Plan'!G57*1)-(('Weekly Operating'!F124-0.03*'Seating Plan'!F26)+0.03*1*'Seating Plan'!F26)),"—") -> 137.22348 | D30: =IF(('Seating Plan'!F26*0.9+'Seating Plan'!G57*0.9)-(('Weekly Operating'!F124-0.03*'Seating Plan'!F26)+0.03*0.9*'Seating Plan'!F26)>0,'Production Budget'!F263/(('Seating Plan'!F26*0.9+'Seating Plan'!G57*0.9)-(('Weekly Operating'!F124-0.03*'Seating Plan'!F26)+0.03*0.9*'Seating Plan'!F26)),"—") -> 227.54243 | E30: =IF(('Seating Plan'!F26*0.8+'Seating Plan'!G57*0.8)-(('Weekly Operating'!F124-0.03*'Seating Plan'!F26)+0.03*0.8*'Seating Plan'!F26)>0,'Production Budget'!F263/(('Seating Plan'!F26*0.8+'Seating Plan'!G57*0.8)-(('Weekly Operating'!F124-0.03*'Seating Plan'!F26)+0.03*0.8*'Seating Plan'!F26)),"—") -> 665.69623 | F30: =IF(('Seating Plan'!F26*0.75+'Seating Plan'!G57*0.75)-(('Weekly Operating'!F124-0.03*'Seating Plan'!F26)+0.03*0.75*'Seating Plan'!F26)>0,'Production Budget'!F263/(('Seating Plan'!F26*0.75+'Seating Plan'!G57*0.75)-(('Weekly Operating'!F124-0.03*'Seating Plan'!F26)+0.03*0.75*'Seating Plan'!F26)),"—") -> 17893.048
B32: Run length: 60 performance weeks. 12 shows/week at 150 capacity. Tiered pricing with community-access tier on every performance.
B33: Not modeled: bar + gift shop + concessions revenue — conservatively adds 15–25% to weekly gross.

Sheet 2. Investor Summary
B2: IF I AWAKEN IN LOS ANGELES
B3: Investor Summary · Confidential
B5: THE OPPORTUNITY
B6: An immersive theatrical journey through six LA neighborhoods in a transformed 30,100 sq ft warehouse.
B7: 60-week run June 2026–August 2027. 12 shows/week. 150-capacity per show.
B9: THE ASK
B10: Total Capitalization | F10: Weekly Gross Potential
B11: ='Production Budget'!F263 -> 6047850.3 | F11: ='Seating Plan'!F26 -> 163000
B13: USE OF FUNDS
B14: Category | C14: Amount | D14: % of Total | E14: What it covers
B15: Build-out & Physical Production | C15: ='Production Budget'!F40 -> 2314250 | D15: =C15/'Production Budget'!F263 -> 0.38265663 | E15: Scenic for 6 environments, LED wall, sound/lighting install, lobby bar/shop, exterior mural
B16: Creative & Management Fees | C16: ='Production Budget'!F90 -> 1008879 | D16: =C16/'Production Budget'!F263 -> 0.16681613 | E16: Director, writer, designers, producers, GM, production manager, union benefits
B17: Pre-Opening Salaries | C17: ='Production Budget'!F135 -> 394919.48 | D17: =C17/'Production Budget'!F263 -> 0.065299149 | E17: 6-week rehearsal+tech+preview period: cast, musicians, SMs, crew
B18: Launch Marketing & Press | C18: ='Production Budget'!F187 -> 775500 | D18: =C18/'Production Budget'!F263 -> 0.12822738 | E18: Pre-opening ad spend, PR, opening night, community partner outreach
B19: Load-In Labor & Venue | C19: ='Production Budget'!F210 -> 190793.6 | D19: =C19/'Production Budget'!F263 -> 0.031547342 | E19: Scenic/electrics/audio load-in, 3-month pre-opening warehouse rent
B20: Casting, Music, Development | C20: ='Production Budget'!F150+'Production Budget'!F166+'Production Budget'!F233 -> 179900 | D20: =C20/'Production Budget'!F263 -> 0.029746107 | E20: Audition space, re-orch, music copying, site-specific R&D
B21: G&A, Legal, Insurance | C21: ='Production Budget'!F225 -> 174700 | D21: =C21/'Production Budget'!F263 -> 0.028886297 | E21: LLC formation, immersive insurance, accounting, travel/housing
B22: Bonds, Deposits, Advances | C22: ='Production Budget'!F252 -> 233500 | D22: =C22/'Production Budget'!F263 -> 0.03860876 | E22: AEA/AFM/SDC/USA bonds, LED vendor deposit, creative advances
B23: Reserve (2-wk preview + 10% contingency) | C23: ='Production Budget'!F261 -> 775408.21 | D23: =C23/'Production Budget'!F263 -> 0.1282122 | E23: Operating reserve and overrun protection
B24: TOTAL CAPITALIZATION | C24: =SUM(C15:C23) -> 6047850.3 | D24: 1
B26: CAPITALIZATION STRUCTURE (Recommended)
B27: Source | C27: Amount | D27: % | E27: Recoupment
B28: Investor Capital | C28: ='Production Budget'!F263*0.55 -> 3326317.7 | D28: 0.55 | E28: Recoupable: 120% + 50% profit share post-recoupment
B29: Institutional Grants (NEA, Mellon, LADF) | C29: ='Production Budget'!F263*0.25 -> 1511962.6 | D29: 0.25 | E29: Non-recoupable (mission-aligned)
B30: Individual Philanthropy / Major Gifts | C30: ='Production Budget'!F263*0.15 -> 907177.54 | D30: 0.15 | E30: Non-recoupable (named sponsorships)
B31: Community / Earned (memberships, crowdfunding) | C31: ='Production Budget'!F263*0.05 -> 302392.51 | D31: 0.05 | E31: Non-recoupable
B33: INVESTOR RETURN SCENARIOS
B34: Avg Capacity | C34: Weekly Contribution | D34: Weeks to Recoup | E34: Investor Recoup* | F34: Within 60-Wk Run?
B35: 100% | C35: =(('Seating Plan'!F26*1)+('Seating Plan'!G57*1))-(('Weekly Operating'!F124-0.03*'Seating Plan'!F26)+0.03*1*'Seating Plan'!F26) -> 44073 | D35: =IF((('Seating Plan'!F26*1)+('Seating Plan'!G57*1))-(('Weekly Operating'!F124-0.03*'Seating Plan'!F26)+0.03*1*'Seating Plan'!F26)>0,'Production Budget'!F263/((('Seating Plan'!F26*1)+('Seating Plan'!G57*1))-(('Weekly Operating'!F124-0.03*'Seating Plan'!F26)+0.03*1*'Seating Plan'!F26)),"—") -> 137.22348 | E35: =IF((('Seating Plan'!F26*1)+('Seating Plan'!G57*1))-(('Weekly Operating'!F124-0.03*'Seating Plan'!F26)+0.03*1*'Seating Plan'!F26)>0,('Production Budget'!F263)*0.55/((('Seating Plan'!F26*1)+('Seating Plan'!G57*1))-(('Weekly Operating'!F124-0.03*'Seating Plan'!F26)+0.03*1*'Seating Plan'!F26)),"—") -> 75.472912 | F35: =IF(AND((('Seating Plan'!F26*1)+('Seating Plan'!G57*1))-(('Weekly Operating'!F124-0.03*'Seating Plan'!F26)+0.03*1*'Seating Plan'!F26)>0,('Production Budget'!F263)*0.55/((('Seating Plan'!F26*1)+('Seating Plan'!G57*1))-(('Weekly Operating'!F124-0.03*'Seating Plan'!F26)+0.03*1*'Seating Plan'!F26))<=60),"YES","NO") -> NO
B36: 90% | C36: =(('Seating Plan'!F26*0.9)+('Seating Plan'!G57*0.9))-(('Weekly Operating'!F124-0.03*'Seating Plan'!F26)+0.03*0.9*'Seating Plan'!F26) -> 26579 | D36: =IF((('Seating Plan'!F26*0.9)+('Seating Plan'!G57*0.9))-(('Weekly Operating'!F124-0.03*'Seating Plan'!F26)+0.03*0.9*'Seating Plan'!F26)>0,'Production Budget'!F263/((('Seating Plan'!F26*0.9)+('Seating Plan'!G57*0.9))-(('Weekly Operating'!F124-0.03*'Seating Plan'!F26)+0.03*0.9*'Seating Plan'!F26)),"—") -> 227.54243 | E36: =IF((('Seating Plan'!F26*0.9)+('Seating Plan'!G57*0.9))-(('Weekly Operating'!F124-0.03*'Seating Plan'!F26)+0.03*0.9*'Seating Plan'!F26)>0,('Production Budget'!F263)*0.55/((('Seating Plan'!F26*0.9)+('Seating Plan'!G57*0.9))-(('Weekly Operating'!F124-0.03*'Seating Plan'!F26)+0.03*0.9*'Seating Plan'!F26)),"—") -> 125.14834 | F36: =IF(AND((('Seating Plan'!F26*0.9)+('Seating Plan'!G57*0.9))-(('Weekly Operating'!F124-0.03*'Seating Plan'!F26)+0.03*0.9*'Seating Plan'!F26)>0,('Production Budget'!F263)*0.55/((('Seating Plan'!F26*0.9)+('Seating Plan'!G57*0.9))-(('Weekly Operating'!F124-0.03*'Seating Plan'!F26)+0.03*0.9*'Seating Plan'!F26))<=60),"YES","NO") -> NO
B37: 85% | C37: =(('Seating Plan'!F26*0.85)+('Seating Plan'!G57*0.85))-(('Weekly Operating'!F124-0.03*'Seating Plan'!F26)+0.03*0.85*'Seating Plan'!F26) -> 17832 | D37: =IF((('Seating Plan'!F26*0.85)+('Seating Plan'!G57*0.85))-(('Weekly Operating'!F124-0.03*'Seating Plan'!F26)+0.03*0.85*'Seating Plan'!F26)>0,'Production Budget'!F263/((('Seating Plan'!F26*0.85)+('Seating Plan'!G57*0.85))-(('Weekly Operating'!F124-0.03*'Seating Plan'!F26)+0.03*0.85*'Seating Plan'!F26)),"—") -> 339.15715 | E37: =IF((('Seating Plan'!F26*0.85)+('Seating Plan'!G57*0.85))-(('Weekly Operating'!F124-0.03*'Seating Plan'!F26)+0.03*0.85*'Seating Plan'!F26)>0,('Production Budget'!F263)*0.55/((('Seating Plan'!F26*0.85)+('Seating Plan'!G57*0.85))-(('Weekly Operating'!F124-0.03*'Seating Plan'!F26)+0.03*0.85*'Seating Plan'!F26)),"—") -> 186.53643 | F37: =IF(AND((('Seating Plan'!F26*0.85)+('Seating Plan'!G57*0.85))-(('Weekly Operating'!F124-0.03*'Seating Plan'!F26)+0.03*0.85*'Seating Plan'!F26)>0,('Production Budget'!F263)*0.55/((('Seating Plan'!F26*0.85)+('Seating Plan'!G57*0.85))-(('Weekly Operating'!F124-0.03*'Seating Plan'!F26)+0.03*0.85*'Seating Plan'!F26))<=60),"YES","NO") -> NO
B38: 80% | C38: =(('Seating Plan'!F26*0.8)+('Seating Plan'!G57*0.8))-(('Weekly Operating'!F124-0.03*'Seating Plan'!F26)+0.03*0.8*'Seating Plan'!F26) -> 9085 | D38: =IF((('Seating Plan'!F26*0.8)+('Seating Plan'!G57*0.8))-(('Weekly Operating'!F124-0.03*'Seating Plan'!F26)+0.03*0.8*'Seating Plan'!F26)>0,'Production Budget'!F263/((('Seating Plan'!F26*0.8)+('Seating Plan'!G57*0.8))-(('Weekly Operating'!F124-0.03*'Seating Plan'!F26)+0.03*0.8*'Seating Plan'!F26)),"—") -> 665.69623 | E38: =IF((('Seating Plan'!F26*0.8)+('Seating Plan'!G57*0.8))-(('Weekly Operating'!F124-0.03*'Seating Plan'!F26)+0.03*0.8*'Seating Plan'!F26)>0,('Production Budget'!F263)*0.55/((('Seating Plan'!F26*0.8)+('Seating Plan'!G57*0.8))-(('Weekly Operating'!F124-0.03*'Seating Plan'!F26)+0.03*0.8*'Seating Plan'!F26)),"—") -> 366.13293 | F38: =IF(AND((('Seating Plan'!F26*0.8)+('Seating Plan'!G57*0.8))-(('Weekly Operating'!F124-0.03*'Seating Plan'!F26)+0.03*0.8*'Seating Plan'!F26)>0,('Production Budget'!F263)*0.55/((('Seating Plan'!F26*0.8)+('Seating Plan'!G57*0.8))-(('Weekly Operating'!F124-0.03*'Seating Plan'!F26)+0.03*0.8*'Seating Plan'!F26))<=60),"YES","NO") -> NO
B39: 75% | C39: =(('Seating Plan'!F26*0.75)+('Seating Plan'!G57*0.75))-(('Weekly Operating'!F124-0.03*'Seating Plan'!F26)+0.03*0.75*'Seating Plan'!F26) -> 338 | D39: =IF((('Seating Plan'!F26*0.75)+('Seating Plan'!G57*0.75))-(('Weekly Operating'!F124-0.03*'Seating Plan'!F26)+0.03*0.75*'Seating Plan'!F26)>0,'Production Budget'!F263/((('Seating Plan'!F26*0.75)+('Seating Plan'!G57*0.75))-(('Weekly Operating'!F124-0.03*'Seating Plan'!F26)+0.03*0.75*'Seating Plan'!F26)),"—") -> 17893.048 | E39: =IF((('Seating Plan'!F26*0.75)+('Seating Plan'!G57*0.75))-(('Weekly Operating'!F124-0.03*'Seating Plan'!F26)+0.03*0.75*'Seating Plan'!F26)>0,('Production Budget'!F263)*0.55/((('Seating Plan'!F26*0.75)+('Seating Plan'!G57*0.75))-(('Weekly Operating'!F124-0.03*'Seating Plan'!F26)+0.03*0.75*'Seating Plan'!F26)),"—") -> 9841.1765 | F39: =IF(AND((('Seating Plan'!F26*0.75)+('Seating Plan'!G57*0.75))-(('Weekly Operating'!F124-0.03*'Seating Plan'!F26)+0.03*0.75*'Seating Plan'!F26)>0,('Production Budget'!F263)*0.55/((('Seating Plan'!F26*0.75)+('Seating Plan'!G57*0.75))-(('Weekly Operating'!F124-0.03*'Seating Plan'!F26)+0.03*0.75*'Seating Plan'!F26))<=60),"YES","NO") -> NO
B40: 70% | C40: =(('Seating Plan'!F26*0.7)+('Seating Plan'!G57*0.7))-(('Weekly Operating'!F124-0.03*'Seating Plan'!F26)+0.03*0.7*'Seating Plan'!F26) -> -8409 | D40: =IF((('Seating Plan'!F26*0.7)+('Seating Plan'!G57*0.7))-(('Weekly Operating'!F124-0.03*'Seating Plan'!F26)+0.03*0.7*'Seating Plan'!F26)>0,'Production Budget'!F263/((('Seating Plan'!F26*0.7)+('Seating Plan'!G57*0.7))-(('Weekly Operating'!F124-0.03*'Seating Plan'!F26)+0.03*0.7*'Seating Plan'!F26)),"—") -> — | E40: =IF((('Seating Plan'!F26*0.7)+('Seating Plan'!G57*0.7))-(('Weekly Operating'!F124-0.03*'Seating Plan'!F26)+0.03*0.7*'Seating Plan'!F26)>0,('Production Budget'!F263)*0.55/((('Seating Plan'!F26*0.7)+('Seating Plan'!G57*0.7))-(('Weekly Operating'!F124-0.03*'Seating Plan'!F26)+0.03*0.7*'Seating Plan'!F26)),"—") -> — | F40: =IF(AND((('Seating Plan'!F26*0.7)+('Seating Plan'!G57*0.7))-(('Weekly Operating'!F124-0.03*'Seating Plan'!F26)+0.03*0.7*'Seating Plan'!F26)>0,('Production Budget'!F263)*0.55/((('Seating Plan'!F26*0.7)+('Seating Plan'!G57*0.7))-(('Weekly Operating'!F124-0.03*'Seating Plan'!F26)+0.03*0.7*'Seating Plan'!F26))<=60),"YES","NO") -> NO
B41: 65% | C41: =(('Seating Plan'!F26*0.65)+('Seating Plan'!G57*0.65))-(('Weekly Operating'!F124-0.03*'Seating Plan'!F26)+0.03*0.65*'Seating Plan'!F26) -> -17156 | D41: =IF((('Seating Plan'!F26*0.65)+('Seating Plan'!G57*0.65))-(('Weekly Operating'!F124-0.03*'Seating Plan'!F26)+0.03*0.65*'Seating Plan'!F26)>0,'Production Budget'!F263/((('Seating Plan'!F26*0.65)+('Seating Plan'!G57*0.65))-(('Weekly Operating'!F124-0.03*'Seating Plan'!F26)+0.03*0.65*'Seating Plan'!F26)),"—") -> — | E41: =IF((('Seating Plan'!F26*0.65)+('Seating Plan'!G57*0.65))-(('Weekly Operating'!F124-0.03*'Seating Plan'!F26)+0.03*0.65*'Seating Plan'!F26)>0,('Production Budget'!F263)*0.55/((('Seating Plan'!F26*0.65)+('Seating Plan'!G57*0.65))-(('Weekly Operating'!F124-0.03*'Seating Plan'!F26)+0.03*0.65*'Seating Plan'!F26)),"—") -> — | F41: =IF(AND((('Seating Plan'!F26*0.65)+('Seating Plan'!G57*0.65))-(('Weekly Operating'!F124-0.03*'Seating Plan'!F26)+0.03*0.65*'Seating Plan'!F26)>0,('Production Budget'!F263)*0.55/((('Seating Plan'!F26*0.65)+('Seating Plan'!G57*0.65))-(('Weekly Operating'!F124-0.03*'Seating Plan'!F26)+0.03*0.65*'Seating Plan'!F26))<=60),"YES","NO") -> NO
B43: *Investor Recoup column = weeks to recoup 55% investor tier only. Grants/philanthropy tiers are non-recoupable.

Sheet 3. Pitch Deck
B2: IF I AWAKEN IN LOS ANGELES
B3: Budget at a Glance
B5: CAPITALIZATION | D5: WEEKLY GROSS POTENTIAL
B6: ='Production Budget'!F263 -> 6047850.3 | D6: ='Seating Plan'!F26 -> 163000
B9: RUN LENGTH | D9: SHOWS PER WEEK
B10: "60 weeks" | D10: 12
B13: VENUE SIZE | D13: SEATS PER SHOW
B14: "30,100 sq ft" | D14: 150
B17: WHERE THE MONEY GOES
B18: Category | D18: Amount | E18: Share
B19: Build & Physical Production | D19: ='Production Budget'!F40+'Production Budget'!F210 -> 2505043.6 | E19: =D19/'Production Budget'!F263 -> 0.41420397
B20: People (Fees + Salaries) | D20: ='Production Budget'!F90+'Production Budget'!F135+'Production Budget'!F150+'Production Budget'!F166 -> 1508698.5 | E20: =D20/'Production Budget'!F263 -> 0.24946029
B21: Marketing & Launch | D21: ='Production Budget'!F187 -> 775500 | E21: =D21/'Production Budget'!F263 -> 0.12822738
B22: G&A, Bonds, Reserve | D22: ='Production Budget'!F225+'Production Budget'!F233+'Production Budget'!F252+'Production Budget'!F261 -> 1258608.2 | E22: =D22/'Production Budget'!F263 -> 0.20810836
B23: TOTAL | D23: =SUM(D19:D22) -> 6047850.3 | E23: 1
B25: ="Breakeven at "&TEXT(Recoupment!C28,"0.0%")&" capacity · Recoup investor tier in "&TEXT('Production Budget'!F263*0.55/(('Seating Plan'!F26*0.9+'Seating Plan'!G57*0.9)-(('Weekly Operating'!F124-0.03*'Seating Plan'!F26)+0.03*0.9*'Seating Plan'!F26)),"0")&" weeks at 90% avg capacity" -> Breakeven at 74.8% capacity · Recoup investor tier in 125 weeks at 90% avg capacity
B27: 60-week run · 12 shows/week · Tiered pricing with community access on every performance

Sheet Summary
A1: NOT FOR DISTRIBUTION
A2: Get Lit Collective / If I Awaken Productions
A3: Los Angeles, CA | info@ifiawaken.com
A4: CONFIDENTIAL | F4: as of: 4/20/26
A6: IF I AWAKEN IN LOS ANGELES
A7: IMMERSIVE THEATRE · LOS ANGELES · BUDGET SUMMARY · v2 (no royalties)
A9: PRODUCTION COSTS (CAPITALIZATION)
B10: (100) PHYSICAL | C10: ='Production Budget'!F40 -> 2314250
B11: (200) FIXED FEES | C11: ='Production Budget'!F90 -> 1008879
B12: (300) SALARIES (Pre-Opening) | C12: ='Production Budget'!F135 -> 394919.48
B13: (400) CASTING / REHEARSAL EXPENSES | C13: ='Production Budget'!F150 -> 53500
B14: (500) MUSIC EXPENSES | C14: ='Production Budget'!F166 -> 51400
B15: (600) ADVERTISING & PROMOTION | C15: ='Production Budget'!F187 -> 775500
B16: (700) VENUE & TECH (Load-In) | C16: ='Production Budget'!F210 -> 190793.6
B17: (800) GENERAL & ADMINISTRATIVE | C17: ='Production Budget'!F225 -> 174700
B18: (900) DEVELOPMENTAL | C18: ='Production Budget'!F233 -> 75000
B19: SUBTOTAL PRODUCTION COSTS: | C19: ='Production Budget'!F235 -> 5038942.1
B21: (950) BONDS, DEPOSITS, ADVANCES | C21: ='Production Budget'!F252 -> 233500
B22: (1000) CONTINGENCY & RESERVE | C22: ='Production Budget'!F261 -> 775408.21
B23: TOTAL CAPITALIZATION: | C23: ='Production Budget'!F263 -> 6047850.3
A26: WEEKLY OPERATING COSTS (NO ROYALTIES)
B27: (1100) PHYSICAL MAINTENANCE | C27: ='Weekly Operating'!F21 -> 9300
B28: (1200) FEES (WEEKLY) | C28: ='Weekly Operating'!F37 -> 8400
B29: (1300) SALARIES (incl. Director + Writer) | C29: ='Weekly Operating'!F84 -> 81007
B30: (1400) ADVERTISING | C30: ='Weekly Operating'!F97 -> 25500
B31: (1500) VENUE & TECH | C31: ='Weekly Operating'!F110 -> 8400
B32: (1600) GENERAL & ADMIN | C32: ='Weekly Operating'!F122 -> 3150
B33: TOTAL WEEKLY OPERATING: | C33: ='Weekly Operating'!F124 -> 135757
A36: WEEKLY GROSS POTENTIAL & KEY METRICS
B37: Weekly Gross Potential (100%): | C37: ='Seating Plan'!F26 -> 163000
B38: Weekly F&B / Merch Net Revenue: | C38: ='Seating Plan'!G57 -> 16830
B39: TOTAL WEEKLY REVENUE (100%): | C39: ='Seating Plan'!F26+'Seating Plan'!G57 -> 179830
B40: Weekly Contribution (100% cap): | C40: ='Seating Plan'!F26+'Seating Plan'!G57-'Weekly Operating'!F124 -> 44073
B41: Weekly Contribution (80% cap est.): | C41: =('Seating Plan'!F26*0.8+'Seating Plan'!G57*0.8)-(('Weekly Operating'!F124-0.03*'Seating Plan'!F26)+0.03*0.8*'Seating Plan'!F26) -> 9085
B43: Breakeven Capacity: | C43: =Recoupment!C28 -> 0.74806791
B44: Weeks to Recoup @ 80% Capacity: | C44: =IF(('Seating Plan'!F26*0.8+'Seating Plan'!G57*0.8)-(('Weekly Operating'!F124-0.03*'Seating Plan'!F26)+0.03*0.8*'Seating Plan'!F26)>0,'Production Budget'!F263/(('Seating Plan'!F26*0.8+'Seating Plan'!G57*0.8)-(('Weekly Operating'!F124-0.03*'Seating Plan'!F26)+0.03*0.8*'Seating Plan'!F26)),"—") -> 665.69623
A47: RECOMMENDED CAPITALIZATION STRUCTURE
B48: Source | C48: Amount | D48: % | E48: Notes
B49: Investor Capital (recoupable + profit share) | C49: =('Production Budget'!F263)*0.55 -> 3326317.7 | D49: 0.55 | E49: 120% recoupment + 50% profits post-recoup (despite no royalties, investors still get profit share).
B50: Institutional Grants (NEA, Mellon, LADF) | C50: =('Production Budget'!F263)*0.25 -> 1511962.6 | D50: 0.25 | E50: Mission-aligned arts funding — no recoupment obligation.
...

Sheet Assumptions
A1: NOT FOR DISTRIBUTION
A2: Get Lit Collective / If I Awaken Productions
A3: Los Angeles, CA | info@ifiawaken.com
A4: CONFIDENTIAL | F4: as of: 4/20/26
A6: ASSUMPTIONS
B8: Rehearsal Weeks | C8: 2 | E8: AEA (Actors + SMs) | F8: SMs only
B9: Tech Weeks | C9: 2 | E9: SDC (Director/Choreographer) | F9: Y
B10: Preview Weeks | C10: 2 | E10: USA (Designers) | F10: Y
B11: Performance Weeks (run) | C11: 60 | E11: AFM Local 47 (Musicians) | F11: Y
B12: Shows per week | C12: 12 | E12: ATPAM (House/Press) | F12: N
B13: Seat Capacity per show | C13: 150 | E13: Contract Type | F13: AEA SM contract
B14: Venue Size (sq ft) | C14: 30100 | E14: Stage Manager (PSM) | F14: 1
B15: Monthly Warehouse Rent | C15: 20000 | E15: Assistant Stage Managers | F15: 2
B16: Performers — Poets/Actors | C16: 9 | E16: Production Assistants | F16: 2
B17: of which AEA | C17: 0 | E17: Board Ops / LED Tech | F17: 2
B18: of which non-union | C18: 9 | E18: Sound / A1 | F18: 1
B19: Performers — Dancers (non-union) | C19: 5 | E19: Wardrobe Supv + Dressers | F19: 3
B20: Performers — Musicians (AFM) | C20: 5 | E20: Props Crew | F20: 1
B21: Understudies / Swings | C21: 4 | E21: Royalty Structure | F21: None
B22: Tour Guides / Wranglers per show | C22: 1
B25: Project Notes:
B26: • Immersive theatre across six themed environments in a 30,100 sq ft LA warehouse (long-term lease, buildout by production).
B27: • Journey: Lobby (bar, gift shop, box office) + Space 1 LED intro -> Space 2 Boyle Heights -> Space 3 Asian
B28: neighborhoods -> Space 4 African-American neighborhoods -> Space 5 Canyons/folk -> Space 6 Concert -> Space 1 reprise.
B29: • Scenic concept: miniature LA — forced-perspective iconic buildings + full-scale street props (e.g., taco stand).
B30: • Premium lighting design: lighting is a primary storytelling device, steering audience focus across 6 environments.
B31: • Performers double as tour guides where narratively appropriate; 3 dedicated wranglers per show.
B32: • Music composed by Derrick Hodge (Grammy); production owns composition rights — no composer fee, no royalty.
B33: • Compressed schedule: 2 rehearsal + 2 tech + 2 preview weeks (6 weeks pre-opening).
B34: • Run: 60 performance weeks, 12 shows/week (Thu–Sun).
B35: • Director: Andrew Scoville (Theater of the Mind, Here Lies Love Assoc., Money Heist: The Experience NYC).
B36: • General Manager: Mark Chinapen. | Producer: Gina.
... B38: • Partial AEA: 6 of 15 poets/actors + all 3 SMs AEA; dancers and remaining 9 poets non-union; musicians AFM Local 47.

Sheet Production Budget
A1: NOT FOR DISTRIBUTION
A4: CONFIDENTIAL | F4: as of: 4/20/26
A6: PRODUCTION BUDGET — IMMERSIVE (150 CAP, 30,100 SQ FT WAREHOUSE)
A7: Cast: 15 Poets/Actors | 5 Dancers | 5 Musicians | 4 Understudies/Swings
A9: (100) PHYSICAL
C10: units | D10: rate | E10: amount | F10: subtotal
A11: (101) | B11: Scenery — Spaces 2/3/4/5 (neighborhood builds) | E11: 750000
A12: (101a) | B12: Scenery — Space 1 (LED lobby/intro) | E12: 35000
A13: (101b) | B13: Scenery — Space 6 (concert stage + seating) | E13: 125000
A14: (101c) | B14: Lobby Bar — Build, Equipment, POS, Inventory | E14: 45000
A15: (101d) | B15: Lobby Gift Shop — Fixtures, Display, POS, Initial Inventory | E15: 20000
A16: (101e) | B16: Lobby Box Office — Counter, Ticketing Hardware, Display | E16: 12000
A17: (102) | B17: Automation / Moving Scenic Elements | E17: 25000
A18: (103) | B18: Costumes — Performers (25 total cast) | C18: 25 | D18: 2000 | E18: =C18*D18 -> 50000
A19: (104) | B19: Understudy Costumes | C19: 4 | D19: 2000 | E19: =C19*D19 -> 8000
A20: (104a) | B20: Wardrobe Perishables | E20: 4500
A21: (105) | B21: Costume Maintenance (pre-show) | E21: 3000
A22: (106) | B22: Electrics Purchase (premium install — 6 spaces) | E22: 200000
A23: (107) | B23: Electrics Rental (Tech) | E23: 22000
A24: (108) | B24: Sound Purchase (install — 6 spaces) | E24: 65000
A25: (109) | B25: Sound Rental (Tech) | E25: 15000
A26: (110) | B26: Props / Furniture (6 spaces) | E26: 140000
A27: (111) | B27: Special Effects (haze, fog, atmospherics) | E27: 15000
A28: (112) | B28: Projections Equipment (non-LED) | E28: 30000
A29: (113) | B29: LED Wall — Purchase (110 ft x 14 ft) | E29: 385000
A30: (113a) | B30: LED Media Servers / Playback Infrastructure | E30: 55000
A31: (113b) | B31: LED Content Creation / Video Production | E31: 75000
A32: (114) | B32: Hair / Wigs / Makeup | E32: 12000
A33: (115) | B33: Designer Expenses | C33: 9 | D33: 750 | E33: =C33*D33 -> 6750
A34: (116) | B34: Departmental Expenses / Hardware | E34: 8000
A35: (117) | B35: Carting / Trucking / Storage | E35: 18000
A36: (118) | B36: Venue Permitting & Occupancy Buildout | E36: 30000
A37: (119) | B37: Security Infrastructure (cameras, access, install, training) | E37: 85000
A38: (120) | B38: Exterior Wall Paint/Mural Wrap (front — ~3,820 sq ft) | E38: 75000
B40: TOTAL 100 — PHYSICAL | F40: =SUM(E11:E38) -> 2314250
A42: (200) FIXED FEES
C43: units | D43: rate | E43: amount | F43: subtotal
A44: (201) | B44: Author / Book Writer (includes 50% of run-period salary) | E44: 110000
A45: (203) | B45: Director — Andrew Scoville (includes 50% of run-period salary) | E45: 125000
A46: (204) | B46: Assistant Director | E46: 12000
...

Sheet Weekly Operating
A1: NOT FOR DISTRIBUTION
A2: CONFIDENTIAL | F2: as of: 4/20/26
A4: WEEKLY OPERATING BUDGET
A5: Per-week costs during 60-week run — NO ROYALTIES model (Director + Writer on salary)
A7: (1100) PHYSICAL MAINTENANCE
C8: units | D8: rate | E8: amount | F8: subtotal
A9: (1101) | B9: Costume Maintenance / Replacements | E9: 800
A10: (1102) | B10: Hair / Makeup Supplies | E10: 500
A11: (1103) | B11: Prop Replacements / Perishables | E11: 600
A12: (1104) | B12: Electrics Maintenance (premium lighting, 6 spaces) | E12: 800
A13: (1105) | B13: LED Wall Service Contract / Parts | E13: 1500
A14: (1106) | B14: Sound Maintenance / Batteries / Parts | E14: 400
A15: (1107) | B15: Scenic Repair / Paint / Hardware | E15: 600
A16: (1108) | B16: Cleaning / Janitorial (30K sqft) | E16: 2500
A17: (1109) | B17: Sanitation / Restroom Supplies | E17: 300
A18: (1110) | B18: Load-Out Accrual (weekly) | E18: 500
A19: (1111) | B19: Bar / Gift Shop — Restocking Allowance | E19: 800
B21: TOTAL 1100 — PHYSICAL MAINTENANCE | F21: =SUM(E9:E19) -> 9300
A23: (1200) FEES (WEEKLY)
C24: units | D24: rate | E24: amount | F24: subtotal
A25: (1201) | B25: General Management (50% — other 50% in prod budget) | E25: 1250
A26: (1202) | B26: Production Supervisor / Resident Director — ELIMINATED | E26: 0
A27: (1203) | B27: Music Director (weekly) — CUT | E27: 0
A28: (1204) | B28: Press Agent (weekly) | E28: 2000
A29: (1205) | B29: Advertising Agency (weekly) | E29: 1500
A30: (1206) | B30: Marketing / Social Media Agency | E30: 1500
A31: (1207) | B31: Casting Director (ongoing) — CUT | E31: 0
A32: (1208) | B32: Accounting / Bookkeeping (weekly) | E32: 1000
A33: (1209) | B33: Legal Retainer | E33: 400
A34: (1210) | B34: Payroll Service | E34: 250
A35: (1211) | B35: Property Manager (weekly) | E35: 500
B37: TOTAL 1200 — FEES | F37: =SUM(E25:E35) -> 8400
A39: (1300) SALARIES (WEEKLY)
C40: units | D40: rate | E40: amount | F40: subtotal
A41: (1300a) | B41: Producer - Diane Lane | C41: 1 | D41: 6730 | E41: =C41*D41 -> 6730
A42: (1300a) | B42: Producer - Brandon Jordan | C42: 1 | D42: 4807 | E42: =C42*D42 -> 4807
A43: (1300a) | B43: Producer - Gina Belafonte | C43: 1 | D43: 961 | E43: =C43*D43 -> 961
A44: (1300a) | B44: Director - Scoville (50% — other 50% in prod budget) | C44: 1 | D44: 1250 | E44: =C44*D44 -> 1250
A45: (1300b) | B45: Writer - Monique (50% — other 50% in prod budget) | C45: 1 | D45: 2885 | E45: =C45*D45 -> 2885
A46: (1301) | B46: Principals — AEA — ELIMINATED (cast now all non-union) | C46: 0 | D46: 1600 | E46: =C46*D46 -> 0
...

Sheet Seating Plan
A1: NOT FOR DISTRIBUTION
A2: CONFIDENTIAL | F2: as of: 4/20/26
A4: SEATING PLAN & GROSS POTENTIAL — TIERED WITHIN-SHOW PRICING
A5: 150-cap immersive · 12 shows/week · Every show has Community pricing
B7: Capacity per Show: | C7: 150
B8: Shows per Week: | C8: 12
B9: Weekly Capacity (seats): | C9: =C7*C8 -> 1800
A11: Day | B11: Tier | C11: Shows/Wk | D11: Seats/Show | E11: Price | F11: Weekly Gross
A12: Thursday — COMMUNITY NIGHT | B12: Community | C12: 2 | D12: 80 | E12: 40 | F12: =C12*D12*E12 -> 6400
B13: Standard | C13: 2 | D13: 50 | E13: 60 | F13: =C13*D13*E13 -> 6000
B14: Premium | C14: 2 | D14: 20 | E14: 80 | F14: =C14*D14*E14 -> 3200
A15: Friday | B15: Community | C15: 2 | D15: 40 | E15: 50 | F15: =C15*D15*E15 -> 4000
B16: Standard | C16: 2 | D16: 70 | E16: 80 | F16: =C16*D16*E16 -> 11200
B17: Premium | C17: 2 | D17: 40 | E17: 110 | F17: =C17*D17*E17 -> 8800
A18: Saturday — PEAK | B18: Community | C18: 4 | D18: 30 | E18: 60 | F18: =C18*D18*E18 -> 7200
B19: Standard | C19: 4 | D19: 50 | E19: 100 | F19: =C19*D19*E19 -> 20000
B20: Premium | C20: 4 | D20: 50 | E20: 140 | F20: =C20*D20*E20 -> 28000
B21: VIP (bar + shop voucher) | C21: 4 | D21: 20 | E21: 185 | F21: =C21*D21*E21 -> 14800
A22: Sunday | B22: Community | C22: 4 | D22: 40 | E22: 55 | F22: =C22*D22*E22 -> 8800
B23: Standard | C23: 4 | D23: 60 | E23: 90 | F23: =C23*D23*E23 -> 21600
B24: Premium | C24: 4 | D24: 50 | E24: 115 | F24: =C24*D24*E24 -> 23000
B26: WEEKLY GROSS POTENTIAL (100%): | F26: =SUM(F12:F24) -> 163000
B27: Weighted Average Ticket Price: | F27: =F26/C9 -> 90.555556
B29: Weekly Community Seats (accessible tier): | F29: =C12*D12+C15*D15+C18*D18+C22*D22 -> 520
B31: Capacity Scenarios:
B32: Capacity % | C32: Weekly Gross | D32: Tickets/Wk | E32: Avg Price
B33: 110% | C33: =F26*1.1 -> 179300 | D33: =C7*C8*1.1 -> 1980 | E33: =C33/D33 -> 90.555556
B34: 100% | C34: =F26*1 -> 163000 | D34: =C7*C8*1 -> 1800 | E34: =C34/D34 -> 90.555556
B35: 90% | C35: =F26*0.9 -> 146700 | D35: =C7*C8*0.9 -> 1620 | E35: =C35/D35 -> 90.555556
B36: 80% | C36: =F26*0.8 -> 130400 | D36: =C7*C8*0.8 -> 1440 | E36: =C36/D36 -> 90.555556
B37: 70% | C37: =F26*0.7 -> 114100 | D37: =C7*C8*0.7 -> 1260 | E37: =C37/D37 -> 90.555556
B38: 60% | C38: =F26*0.6 -> 97800 | D38: =C7*C8*0.6 -> 1080 | E38: =C38/D38 -> 90.555556
B39: 50% | C39: =F26*0.5 -> 81500 | D39: =C7*C8*0.5 -> 900 | E39: =C39/D39 -> 90.555556
B41: Pricing Philosophy:
B42: • Within-show tiered pricing: every performance has Community seats — accessibility is built into every show, not isolated to one night.
B43: • Community tier ($40-60) = accessible for students, LA neighborhood partners, Get Lit alumni, nonprofit coalitions.
B44: • Standard tier = market-rate ticket for general audience.
B45: • Premium tier = committed theatergoers / tourists / immersive enthusiasts.
B46: • VIP tier (Saturday only, 20 seats/show) = bar credit + gift shop voucher + priority entry. Effectively subsidizes Community tier.
B47: • Weighted avg ~$91/ticket (vs. $99 in v2) — meaningful reduction via access tier on every performance.
...

Sheet Recoupment
A1: NOT FOR DISTRIBUTION
A4: CONFIDENTIAL | F4: as of: 4/20/26
A6: RECOUPMENT SCHEDULE
A7: Weeks to recoup capitalization — no-royalty model
B9: Total Capitalization: | C9: ='Production Budget'!F263 -> 6047850.3
B10: Weekly Operating Cost (at 100% GWBOR): | C10: ='Weekly Operating'!F124 -> 135757
B11: Weekly Gross Potential (100%): | C11: ='Seating Plan'!F26 -> 163000
B13: Capacity % | C13: Weekly GWBOR | D13: Weekly Op Cost | E13: Total Contrib. (Tix+F&B−Op) | F13: Weeks to Recoup | G13: Months to Recoup
B14: 110% | C14: =C11*1.1 -> 179300 | D14: =(C10-0.03*C11)+0.03*C14 -> 136246 | E14: =C14+('Seating Plan'!G57*1.1)-D14 -> 61567 | F14: =IF(E14>0,C9/E14,"—") -> 98.232012 | G14: =IF(E14>0,F14/4.33,"—") -> 22.686377
B15: 100% | C15: =C11*1 -> 163000 | D15: =(C10-0.03*C11)+0.03*C15 -> 135757 | E15: =C15+('Seating Plan'!G57*1)-D15 -> 44073 | F15: =IF(E15>0,C9/E15,"—") -> 137.22348 | G15: =IF(E15>0,F15/4.33,"—") -> 31.691334
B16: 95% | C16: =C11*0.95 -> 154850 | D16: =(C10-0.03*C11)+0.03*C16 -> 135512.5 | E16: =C16+('Seating Plan'!G57*0.95)-D16 -> 35326 | F16: =IF(E16>0,C9/E16,"—") -> 171.20111 | G16: =IF(E16>0,F16/4.33,"—") -> 39.538362
B17: 90% | C17: =C11*0.9 -> 146700 | D17: =(C10-0.03*C11)+0.03*C17 -> 135268 | E17: =C17+('Seating Plan'!G57*0.9)-D17 -> 26579 | F17: =IF(E17>0,C9/E17,"—") -> 227.54243 | G17: =IF(E17>0,F17/4.33,"—") -> 52.550215
B18: 85% | C18: =C11*0.85 -> 138550 | D18: =(C10-0.03*C11)+0.03*C18 -> 135023.5 | E18: =C18+('Seating Plan'!G57*0.85)-D18 -> 17832 | F18: =IF(E18>0,C9/E18,"—") -> 339.15715 | G18: =IF(E18>0,F18/4.33,"—") -> 78.327286
B19: 80% | C19: =C11*0.8 -> 130400 | D19: =(C10-0.03*C11)+0.03*C19 -> 134779 | E19: =C19+('Seating Plan'!G57*0.8)-D19 -> 9085 | F19: =IF(E19>0,C9/E19,"—") -> 665.69623 | G19: =IF(E19>0,F19/4.33,"—") -> 153.74047
B20: 75% | C20: =C11*0.75 -> 122250 | D20: =(C10-0.03*C11)+0.03*C20 -> 134534.5 | E20: =C20+('Seating Plan'!G57*0.75)-D20 -> 338 | F20: =IF(E20>0,C9/E20,"—") -> 17893.048 | G20: =IF(E20>0,F20/4.33,"—") -> 4132.3437
B21: 70% | C21: =C11*0.7 -> 114100 | D21: =(C10-0.03*C11)+0.03*C21 -> 134290 | E21: =C21+('Seating Plan'!G57*0.7)-D21 -> -8409 | F21: =IF(E21>0,C9/E21,"—") -> — | G21: =IF(E21>0,F21/4.33,"—") -> —
B22: 65% | C22: =C11*0.65 -> 105950 | D22: =(C10-0.03*C11)+0.03*C22 -> 134045.5 | E22: =C22+('Seating Plan'!G57*0.65)-D22 -> -17156 | F22: =IF(E22>0,C9/E22,"—") -> — | G22: =IF(E22>0,F22/4.33,"—") -> —
B23: 60% | C23: =C11*0.6 -> 97800 | D23: =(C10-0.03*C11)+0.03*C23 -> 133801 | E23: =C23+('Seating Plan'!G57*0.6)-D23 -> -25903 | F23: =IF(E23>0,C9/E23,"—") -> — | G23: =IF(E23>0,F23/4.33,"—") -> —
B24: 55% | C24: =C11*0.55 -> 89650 | D24: =(C10-0.03*C11)+0.03*C24 -> 133556.5 | E24: =C24+('Seating Plan'!G57*0.55)-D24 -> -34650 | F24: =IF(E24>0,C9/E24,"—") -> — | G24: =IF(E24>0,F24/4.33,"—") -> —
B25: 50% | C25: =C11*0.5 -> 81500 | D25: =(C10-0.03*C11)+0.03*C25 -> 133312 | E25: =C25+('Seating Plan'!G57*0.5)-D25 -> -43397 | F25: =IF(E25>0,C9/E25,"—") -> — | G25: =IF(E25>0,F25/4.33,"—") -> —
B26: 45% | C26: =C11*0.45 -> 73350 | D26: =(C10-0.03*C11)+0.03*C26 -> 133067.5 | E26: =C26+('Seating Plan'!G57*0.45)-D26 -> -52144 | F26: =IF(E26>0,C9/E26,"—") -> — | G26: =IF(E26>0,F26/4.33,"—") -> —
B28: BREAKEVEN CAPACITY: | C28: =('Weekly Operating'!F124-0.03*'Seating Plan'!F26)/(0.97*'Seating Plan'!F26+'Seating Plan'!G57) -> 0.74806791
B29: Breakeven Weekly GWBOR: | C29: =C28*C11 -> 121935.07
B30: Breakeven Avg Tickets / Show: | C30: =C28*150 -> 112.21019
B32: Notes:
B33: • REVISED: Weekly contribution now includes F&B/Merch net revenue ($XX/wk at 100%) — see Seating Plan.
B34: • Only ~3% of weekly op varies with capacity (CC fees). No royalties means far more fixed overhead.
B35: • NO ROYALTY model means breakeven is determined almost entirely by fixed weekly operating costs.
B36: • Show scheduled for 60-week run; any scenario requiring >60 weeks does not recoup within the run.
B37: • Does NOT include bar, gift shop, concessions revenue — these are real upside with expanded lobby.
B38: • Bar + gift shop could add 15-25% to gross revenue — conservative models add $15-30K/wk.
B39: • Without royalties, creative team has zero upside participation — may limit future revivals/licensing.

Sheet Events Upside
A1: NOT FOR DISTRIBUTION
A4: CONFIDENTIAL | F4: as of: 4/27/26
A6: EVENTS / SECOND BUSINESS — UPSIDE SCENARIO
A7: Venue rentals on dark days (Mon–Wed + weekday daytime). NOT included in main budget recoupment math.
A9: OPPORTUNITY CONTEXT
B10: The show occupies the venue Thu–Sun evenings + weekend afternoons. Mon–Wed and weekday daytime sit dark.
B11: That's ~3.5 fully rentable days/week × 60 weeks = ~210 day-equivalents of unused premium real estate.
A13: VENUE ASSETS (LA Market Rates)
B14: Asset | C14: Low ($/day) | D14: High ($/day) | E14: Notes
B15: 110-ft permanent LED wall | C15: 5000 | D15: 20000 | E15: LA's most dramatic indoor screen
B16: Real bar program | C16: 8000 | D16: 15000 | E16: 64-ft bar, neon, leather booths, VIP zone
B17: 150-seat proscenium theater | C17: 5000 | D17: 10000 | E17: With stage
B18: Outdoor red-carpet courtyard | C18: 3000 | D18: 10000 | E18: With marquee — premiere-tier, rare in LA
B19: 30,000 sq ft of versatile space | C19: 10000 | D19: 18000 | E19: 500+ guest cocktail capacity
B20: Arts District location | C20: — | D20: — | E20: Premium real estate; included in above
A22: WHAT WE SELL
B23: Offering | C23: Low Rate | D23: High Rate | E23: Use Case
B24: Full venue buyout | C24: 25000 | D24: 45000 | E24: Premieres, brand activations, wrap parties
B25: Single-space rental | C25: 6000 | D25: 12000 | E25: All-hands, product launches, dinners
B26: Production / filming day rate | C26: 8000 | D26: 18000 | E26: Music videos, commercials, photo shoots
B27: Recurring programs | C27: 2000 | D27: 5000 | E27: Comedy nights, podcast tapings, salons
A29: RUN-PERIOD REVENUE SCENARIOS (60 weeks)
B30: Scenario | C30: Utilization | D30: Avg Day Rate | E30: Run Gross | F30: Direct Costs | G30: Run Net
B31: Conservative | C31: 0.3 | D31: 8500 | E31: =210*C31*D31 -> 535500 | F31: =E31*0.25 -> 133875 | G31: =E31-F31-98000 -> 303625
B32: Moderate | C32: 0.5 | D32: 10750 | E32: =210*C32*D32 -> 1128750 | F32: =E32*0.25 -> 282187.5 | G32: =E32-F32-98000 -> 748562.5
B33: Aggressive | C33: 0.65 | D33: 13350 | E33: =210*C33*D33 -> 1822275 | F33: =E33*0.25 -> 455568.75 | G33: =E33-F33-98000 -> 1268706.2
A35: WHAT IT COSTS TO UNLOCK
B36: Director of Venue Sales & Events: | D36: 85000 | E36: /year
B37: The only line required to make this real. Pays for itself in 6–8 events. Not currently in main budget.
A39: COMBINED PICTURE (Budget + Events Upside)
B40: Total Capitalization (no change): | D40: ='Production Budget'!F263 -> 6047850.3
B41: Investor Tier (55%): | D41: ='Production Budget'!F263*0.55 -> 3326317.7
B43: Show Weekly Contribution @ 80% capacity: | D43: =(('Seating Plan'!F26*0.8)+('Seating Plan'!G57*0.8))-(('Weekly Operating'!F124-0.03*'Seating Plan'!F26)+0.03*0.8*'Seating Plan'!F26) -> 9085
B44: Events Net Contribution (weekly avg):
B45: Conservative scenario: | D45: =G31/60 -> 5060.4167 | F45: =D43+D45 -> 14145.417 | G45: /wk total
B46: Moderate scenario: | D46: =G32/60 -> 12476.042 | F46: =D43+D46 -> 21561.042 | G46: /wk total
B47: Aggressive scenario: | D47: =G33/60 -> 21145.104 | F47: =D43+D47 -> 30230.104 | G47: /wk total
B49: Notes:
B50: • This sheet models the second-business opportunity from the dark days (Mon-Wed + weekday daytime).
B51: • Numbers are NOT included in the main Recoupment math — treat as upside scenario only.
...
