Workbook

Sheet 1. Exec One-Pager
B2: IF I AWAKEN IN LOS ANGELES
B3: Immersive theatre · 30,100 sq ft · 150-cap · 60-week Los Angeles run
B5: THE ASK | E5: KEY METRICS
B6: ='Production Budget'!F263 -> 5965767.3 | E6: Weekly Gross Potential (100%) | F6: ='Seating Plan'!F28 -> 163000
E7: Weekly Operating Cost | F7: ='Weekly Operating'!F123 -> 106265.5
E8: Weekly Contribution @ 100% | F8: ='Seating Plan'!F28-'Weekly Operating'!F123 -> 56734.5
B9: Total Capitalization Required | E9: Breakeven Capacity | F9: =Recoupment!C28 -> 0.6411707
E10: Avg Ticket Price (weighted) | F10: ='Seating Plan'!F28/'Seating Plan'!C11 -> 90.555556
B12: CAPITALIZATION BREAKDOWN | E12: WEEKLY OPERATING COSTS
B13: Scenic / Physical Production | C13: ='Production Budget'!F40 -> 2314250 | E13: Physical Maintenance | F13: ='Weekly Operating'!F23 -> 9300
B14: Creative & Management Fees | C14: ='Production Budget'!F90 -> 1008879 | E14: Fees (GM, PR, Marketing, Legal) | F14: ='Weekly Operating'!F39 -> 7900
B15: Pre-Opening Salaries | C15: ='Production Budget'!F135 -> 394919.48 | E15: Weekly Salaries (all staff) | F15: ='Weekly Operating'!F83 -> 67415.5
B16: Casting & Rehearsal | C16: ='Production Budget'!F150 -> 53500 | E16: Weekly Advertising | F16: ='Weekly Operating'!F96 -> 10100
B17: Music | C17: ='Production Budget'!F166 -> 51400 | E17: Venue & Tech (rent, utilities, CC) | F17: ='Weekly Operating'!F109 -> 8400
B18: Advertising & Launch | C18: ='Production Budget'!F187 -> 754500 | E18: General & Administrative | F18: ='Weekly Operating'!F121 -> 3150
B19: Venue Load-In & Tech Labor | C19: ='Production Budget'!F210 -> 190793.6
B20: General & Administrative | C20: ='Production Budget'!F225 -> 174700
B21: Developmental | C21: ='Production Budget'!F233 -> 75000 | E21: TOTAL WEEKLY OPERATING | F21: ='Weekly Operating'!F123 -> 106265.5
B22: Subtotal: Production Costs | C22: ='Production Budget'!F235 -> 5017942.1
B23: Bonds, Deposits, Advances | C23: ='Production Budget'!F252 -> 233500
B24: Reserve & 10% Contingency | C24: ='Production Budget'!F261 -> 714325.21
B25: TOTAL CAPITALIZATION | C25: ='Production Budget'!F263 -> 5965767.3
B26: RECOUPMENT AT CAPACITY SCENARIOS
B27: Capacity | C27: 100% | D27: 90% | E27: 80% | F27: 75% | G27: 70%
B28: Weekly Contribution | C28: =('Seating Plan'!F28*1)-(('Weekly Operating'!F123-0.03*'Seating Plan'!F28)+0.03*1*'Seating Plan'!F28) -> 56734.5 | D28: =('Seating Plan'!F28*0.9)-(('Weekly Operating'!F123-0.03*'Seating Plan'!F28)+0.03*0.9*'Seating Plan'!F28) -> 40923.5 | E28: =('Seating Plan'!F28*0.8)-(('Weekly Operating'!F123-0.03*'Seating Plan'!F28)+0.03*0.8*'Seating Plan'!F28) -> 25112.5 | F28: =('Seating Plan'!F28*0.75)-(('Weekly Operating'!F123-0.03*'Seating Plan'!F28)+0.03*0.75*'Seating Plan'!F28) -> 17207 | G28: =('Seating Plan'!F28*0.7)-(('Weekly Operating'!F123-0.03*'Seating Plan'!F28)+0.03*0.7*'Seating Plan'!F28) -> 9301.5
B29: Weeks to Recoup | C29: =IF(('Seating Plan'!F28*1-(('Weekly Operating'!F123-0.03*'Seating Plan'!F28)+0.03*1*'Seating Plan'!F28))>0,'Production Budget'!F263/('Seating Plan'!F28*1-(('Weekly Operating'!F123-0.03*'Seating Plan'!F28)+0.03*1*'Seating Plan'!F28)),"—") -> 105.15237 | D29: =IF(('Seating Plan'!F28*0.9-(('Weekly Operating'!F123-0.03*'Seating Plan'!F28)+0.03*0.9*'Seating Plan'!F28))>0,'Production Budget'!F263/('Seating Plan'!F28*0.9-(('Weekly Operating'!F123-0.03*'Seating Plan'!F28)+0.03*0.9*'Seating Plan'!F28)),"—") -> 145.77852 | E29: =IF(('Seating Plan'!F28*0.8-(('Weekly Operating'!F123-0.03*'Seating Plan'!F28)+0.03*0.8*'Seating Plan'!F28))>0,'Production Budget'!F263/('Seating Plan'!F28*0.8-(('Weekly Operating'!F123-0.03*'Seating Plan'!F28)+0.03*0.8*'Seating Plan'!F28)),"—") -> 237.56166 | F29: =IF(('Seating Plan'!F28*0.75-(('Weekly Operating'!F123-0.03*'Seating Plan'!F28)+0.03*0.75*'Seating Plan'!F28))>0,'Production Budget'!F263/('Seating Plan'!F28*0.75-(('Weekly Operating'!F123-0.03*'Seating Plan'!F28)+0.03*0.75*'Seating Plan'!F28)),"—") -> 346.70583 | G29: =IF(('Seating Plan'!F28*0.7-(('Weekly Operating'!F123-0.03*'Seating Plan'!F28)+0.03*0.7*'Seating Plan'!F28))>0,'Production Budget'!F263/('Seating Plan'!F28*0.7-(('Weekly Operating'!F123-0.03*'Seating Plan'!F28)+0.03*0.7*'Seating Plan'!F28)),"—") -> 641.37691
B31: Run length: 60 performance weeks. 12 shows/week at 150 capacity. Tiered pricing with community-access tier on every performance.
B32: Not modeled: bar + gift shop + concessions revenue — conservatively adds 15–25% to weekly gross.

Sheet 2. Investor Summary
B2: IF I AWAKEN IN LOS ANGELES
B3: Investor Summary · Confidential
B5: THE OPPORTUNITY
B6: An immersive theatrical journey through six LA neighborhoods in a transformed 30,100 sq ft warehouse.
B7: Written and scored by Derrick Hodge (Grammy winner). Directed by Andrew Scoville (Here Lies Love Associate;
B8: Theater of the Mind; Money Heist: The Experience NYC). Pilot at The Ford in August 2025 sold out (1,000+ attended).
B9: 60-week run June 2026–August 2027. 12 shows/week. 150-capacity per show.
B11: THE ASK
B12: Total Capitalization | D12: Investor Tier (55%) | F12: Weekly Gross Potential
B13: ='Production Budget'!F263 -> 5965767.3 | D13: ='Production Budget'!F263*0.55 -> 3281172 | F13: ='Seating Plan'!F28 -> 163000
B15: USE OF FUNDS
B16: Category | C16: Amount | D16: % of Total | E16: What it covers
B17: Build-out & Physical Production | C17: ='Production Budget'!F40 -> 2314250 | D17: =C17/'Production Budget'!F263 -> 0.3879216 | E17: Scenic for 6 environments, LED wall, sound/lighting install, lobby bar/shop, exterior mural
B18: Creative & Management Fees | C18: ='Production Budget'!F90 -> 1008879 | D18: =C18/'Production Budget'!F263 -> 0.16911136 | E18: Director, writer, designers, producers, GM, production manager, union benefits
B19: Pre-Opening Salaries | C19: ='Production Budget'!F135 -> 394919.48 | D19: =C19/'Production Budget'!F263 -> 0.066197601 | E19: 6-week rehearsal+tech+preview period: cast, musicians, SMs, crew
B20: Launch Marketing & Press | C20: ='Production Budget'!F187 -> 754500 | D20: =C20/'Production Budget'!F263 -> 0.12647158 | E20: Pre-opening ad spend, PR, opening night, community partner outreach
B21: Load-In Labor & Venue | C21: ='Production Budget'!F210 -> 190793.6 | D21: =C21/'Production Budget'!F263 -> 0.031981402 | E21: Scenic/electrics/audio load-in, 3-month pre-opening warehouse rent
B22: Casting, Music, Development | C22: ='Production Budget'!F150+'Production Budget'!F166+'Production Budget'!F233 -> 179900 | D22: =C22/'Production Budget'!F263 -> 0.030155383 | E22: Audition space, re-orch, music copying, site-specific R&D
B23: G&A, Legal, Insurance | C23: ='Production Budget'!F225 -> 174700 | D23: =C23/'Production Budget'!F263 -> 0.029283744 | E23: LLC formation, immersive insurance, accounting, travel/housing
B24: Bonds, Deposits, Advances | C24: ='Production Budget'!F252 -> 233500 | D24: =C24/'Production Budget'!F263 -> 0.039139978 | E24: AEA/AFM/SDC/USA bonds, LED vendor deposit, creative advances
B25: Reserve (2-wk preview + 10% contingency) | C25: ='Production Budget'!F261 -> 714325.21 | D25: =C25/'Production Budget'!F263 -> 0.11973736 | E25: Operating reserve and overrun protection
B26: TOTAL CAPITALIZATION | C26: =SUM(C17:C25) -> 5965767.3 | D26: 1
B28: CAPITALIZATION STRUCTURE (Recommended)
B29: Source | C29: Amount | D29: % | E29: Recoupment
B30: Investor Capital | C30: ='Production Budget'!F263*0.55 -> 3281172 | D30: 0.55 | E30: Recoupable: 120% + 50% profit share post-recoupment
B31: Institutional Grants (NEA, Mellon, LADF) | C31: ='Production Budget'!F263*0.25 -> 1491441.8 | D31: 0.25 | E31: Non-recoupable (mission-aligned)
B32: Individual Philanthropy / Major Gifts | C32: ='Production Budget'!F263*0.15 -> 894865.09 | D32: 0.15 | E32: Non-recoupable (named sponsorships)
B33: Community / Earned (memberships, crowdfunding) | C33: ='Production Budget'!F263*0.05 -> 298288.36 | D33: 0.05 | E33: Non-recoupable
B35: INVESTOR RETURN SCENARIOS
B36: Avg Capacity | C36: Weekly Contribution | D36: Weeks to Recoup | E36: Investor Recoup* | F36: Within 60-Wk Run?
B37: 100% | C37: =(('Seating Plan'!F28*1)-(('Weekly Operating'!F123-0.03*'Seating Plan'!F28)+0.03*1*'Seating Plan'!F28)) -> 56734.5 | D37: =IF((('Seating Plan'!F28*1)-(('Weekly Operating'!F123-0.03*'Seating Plan'!F28)+0.03*1*'Seating Plan'!F28))>0,'Production Budget'!F263/(('Seating Plan'!F28*1)-(('Weekly Operating'!F123-0.03*'Seating Plan'!F28)+0.03*1*'Seating Plan'!F28)),"—") -> 105.15237 | E37: =IF((('Seating Plan'!F28*1)-(('Weekly Operating'!F123-0.03*'Seating Plan'!F28)+0.03*1*'Seating Plan'!F28))>0,'Production Budget'!F263*0.55/(('Seating Plan'!F28*1)-(('Weekly Operating'!F123-0.03*'Seating Plan'!F28)+0.03*1*'Seating Plan'!F28)),"—") -> 57.833805 | F37: =IF(AND((('Seating Plan'!F28*1)-(('Weekly Operating'!F123-0.03*'Seating Plan'!F28)+0.03*1*'Seating Plan'!F28))>0,'Production Budget'!F263*0.55/(('Seating Plan'!F28*1)-(('Weekly Operating'!F123-0.03*'Seating Plan'!F28)+0.03*1*'Seating Plan'!F28))<=60),"YES","NO") -> YES
B38: 90% | C38: =(('Seating Plan'!F28*0.9)-(('Weekly Operating'!F123-0.03*'Seating Plan'!F28)+0.03*0.9*'Seating Plan'!F28)) -> 40923.5 | D38: =IF((('Seating Plan'!F28*0.9)-(('Weekly Operating'!F123-0.03*'Seating Plan'!F28)+0.03*0.9*'Seating Plan'!F28))>0,'Production Budget'!F263/(('Seating Plan'!F28*0.9)-(('Weekly Operating'!F123-0.03*'Seating Plan'!F28)+0.03*0.9*'Seating Plan'!F28)),"—") -> 145.77852 | E38: =IF((('Seating Plan'!F28*0.9)-(('Weekly Operating'!F123-0.03*'Seating Plan'!F28)+0.03*0.9*'Seating Plan'!F28))>0,'Production Budget'!F263*0.55/(('Seating Plan'!F28*0.9)-(('Weekly Operating'!F123-0.03*'Seating Plan'!F28)+0.03*0.9*'Seating Plan'!F28)),"—") -> 80.178186 | F38: =IF(AND((('Seating Plan'!F28*0.9)-(('Weekly Operating'!F123-0.03*'Seating Plan'!F28)+0.03*0.9*'Seating Plan'!F28))>0,'Production Budget'!F263*0.55/(('Seating Plan'!F28*0.9)-(('Weekly Operating'!F123-0.03*'Seating Plan'!F28)+0.03*0.9*'Seating Plan'!F28))<=60),"YES","NO") -> NO
B39: 85% | C39: =(('Seating Plan'!F28*0.85)-(('Weekly Operating'!F123-0.03*'Seating Plan'!F28)+0.03*0.85*'Seating Plan'!F28)) -> 33018 | D39: =IF((('Seating Plan'!F28*0.85)-(('Weekly Operating'!F123-0.03*'Seating Plan'!F28)+0.03*0.85*'Seating Plan'!F28))>0,'Production Budget'!F263/(('Seating Plan'!F28*0.85)-(('Weekly Operating'!F123-0.03*'Seating Plan'!F28)+0.03*0.85*'Seating Plan'!F28)),"—") -> 180.68227 | E39: =IF((('Seating Plan'!F28*0.85)-(('Weekly Operating'!F123-0.03*'Seating Plan'!F28)+0.03*0.85*'Seating Plan'!F28))>0,'Production Budget'!F263*0.55/(('Seating Plan'!F28*0.85)-(('Weekly Operating'!F123-0.03*'Seating Plan'!F28)+0.03*0.85*'Seating Plan'!F28)),"—") -> 99.37525 | F39: =IF(AND((('Seating Plan'!F28*0.85)-(('Weekly Operating'!F123-0.03*'Seating Plan'!F28)+0.03*0.85*'Seating Plan'!F28))>0,'Production Budget'!F263*0.55/(('Seating Plan'!F28*0.85)-(('Weekly Operating'!F123-0.03*'Seating Plan'!F28)+0.03*0.85*'Seating Plan'!F28))<=60),"YES","NO") -> NO
B40: 80% | C40: =(('Seating Plan'!F28*0.8)-(('Weekly Operating'!F123-0.03*'Seating Plan'!F28)+0.03*0.8*'Seating Plan'!F28)) -> 25112.5 | D40: =IF((('Seating Plan'!F28*0.8)-(('Weekly Operating'!F123-0.03*'Seating Plan'!F28)+0.03*0.8*'Seating Plan'!F28))>0,'Production Budget'!F263/(('Seating Plan'!F28*0.8)-(('Weekly Operating'!F123-0.03*'Seating Plan'!F28)+0.03*0.8*'Seating Plan'!F28)),"—") -> 237.56166 | E40: =IF((('Seating Plan'!F28*0.8)-(('Weekly Operating'!F123-0.03*'Seating Plan'!F28)+0.03*0.8*'Seating Plan'!F28))>0,'Production Budget'!F263*0.55/(('Seating Plan'!F28*0.8)-(('Weekly Operating'!F123-0.03*'Seating Plan'!F28)+0.03*0.8*'Seating Plan'!F28)),"—") -> 130.65892 | F40: =IF(AND((('Seating Plan'!F28*0.8)-(('Weekly Operating'!F123-0.03*'Seating Plan'!F28)+0.03*0.8*'Seating Plan'!F28))>0,'Production Budget'!F263*0.55/(('Seating Plan'!F28*0.8)-(('Weekly Operating'!F123-0.03*'Seating Plan'!F28)+0.03*0.8*'Seating Plan'!F28))<=60),"YES","NO") -> NO
B41: 75% | C41: =(('Seating Plan'!F28*0.75)-(('Weekly Operating'!F123-0.03*'Seating Plan'!F28)+0.03*0.75*'Seating Plan'!F28)) -> 17207 | D41: =IF((('Seating Plan'!F28*0.75)-(('Weekly Operating'!F123-0.03*'Seating Plan'!F28)+0.03*0.75*'Seating Plan'!F28))>0,'Production Budget'!F263/(('Seating Plan'!F28*0.75)-(('Weekly Operating'!F123-0.03*'Seating Plan'!F28)+0.03*0.75*'Seating Plan'!F28)),"—") -> 346.70583 | E41: =IF((('Seating Plan'!F28*0.75)-(('Weekly Operating'!F123-0.03*'Seating Plan'!F28)+0.03*0.75*'Seating Plan'!F28))>0,'Production Budget'!F263*0.55/(('Seating Plan'!F28*0.75)-(('Weekly Operating'!F123-0.03*'Seating Plan'!F28)+0.03*0.75*'Seating Plan'!F28)),"—") -> 190.68821 | F41: =IF(AND((('Seating Plan'!F28*0.75)-(('Weekly Operating'!F123-0.03*'Seating Plan'!F28)+0.03*0.75*'Seating Plan'!F28))>0,'Production Budget'!F263*0.55/(('Seating Plan'!F28*0.75)-(('Weekly Operating'!F123-0.03*'Seating Plan'!F28)+0.03*0.75*'Seating Plan'!F28))<=60),"YES","NO") -> NO
B42: 70% | C42: =(('Seating Plan'!F28*0.7)-(('Weekly Operating'!F123-0.03*'Seating Plan'!F28)+0.03*0.7*'Seating Plan'!F28)) -> 9301.5 | D42: =IF((('Seating Plan'!F28*0.7)-(('Weekly Operating'!F123-0.03*'Seating Plan'!F28)+0.03*0.7*'Seating Plan'!F28))>0,'Production Budget'!F263/(('Seating Plan'!F28*0.7)-(('Weekly Operating'!F123-0.03*'Seating Plan'!F28)+0.03*0.7*'Seating Plan'!F28)),"—") -> 641.37691 | E42: =IF((('Seating Plan'!F28*0.7)-(('Weekly Operating'!F123-0.03*'Seating Plan'!F28)+0.03*0.7*'Seating Plan'!F28))>0,'Production Budget'!F263*0.55/(('Seating Plan'!F28*0.7)-(('Weekly Operating'!F123-0.03*'Seating Plan'!F28)+0.03*0.7*'Seating Plan'!F28)),"—") -> 352.7573 | F42: =IF(AND((('Seating Plan'!F28*0.7)-(('Weekly Operating'!F123-0.03*'Seating Plan'!F28)+0.03*0.7*'Seating Plan'!F28))>0,'Production Budget'!F263*0.55/(('Seating Plan'!F28*0.7)-(('Weekly Operating'!F123-0.03*'Seating Plan'!F28)+0.03*0.7*'Seating Plan'!F28))<=60),"YES","NO") -> NO
B43: 65% | C43: =(('Seating Plan'!F28*0.65)-(('Weekly Operating'!F123-0.03*'Seating Plan'!F28)+0.03*0.65*'Seating Plan'!F28)) -> 1396 | D43: =IF((('Seating Plan'!F28*0.65)-(('Weekly Operating'!F123-0.03*'Seating Plan'!F28)+0.03*0.65*'Seating Plan'!F28))>0,'Production Budget'!F263/(('Seating Plan'!F28*0.65)-(('Weekly Operating'!F123-0.03*'Seating Plan'!F28)+0.03*0.65*'Seating Plan'!F28)),"—") -> 4273.4723 | E43: =IF((('Seating Plan'!F28*0.65)-(('Weekly Operating'!F123-0.03*'Seating Plan'!F28)+0.03*0.65*'Seating Plan'!F28))>0,'Production Budget'!F263*0.55/(('Seating Plan'!F28*0.65)-(('Weekly Operating'!F123-0.03*'Seating Plan'!F28)+0.03*0.65*'Seating Plan'!F28)),"—") -> 2350.4097 | F43: =IF(AND((('Seating Plan'!F28*0.65)-(('Weekly Operating'!F123-0.03*'Seating Plan'!F28)+0.03*0.65*'Seating Plan'!F28))>0,'Production Budget'!F263*0.55/(('Seating Plan'!F28*0.65)-(('Weekly Operating'!F123-0.03*'Seating Plan'!F28)+0.03*0.65*'Seating Plan'!F28))<=60),"YES","NO") -> NO
B45: *Investor Recoup column = weeks to recoup 55% investor tier only. Grants/philanthropy tiers are non-recoupable.
B47: KEY RISK FACTORS
B48: • Breakeven requires ~86% average capacity — tight for a new immersive, though pilot oversold indicates strong demand.
...

Sheet 3. Pitch Deck
B2: IF I AWAKEN IN LOS ANGELES
B3: Budget at a Glance
B5: CAPITALIZATION | D5: WEEKLY GROSS POTENTIAL
B6: ='Production Budget'!F263 -> 5965767.3 | D6: ='Seating Plan'!F28 -> 163000
B9: RUN LENGTH | D9: SHOWS PER WEEK
B10: "60 weeks" | D10: 12
B13: VENUE SIZE | D13: SEATS PER SHOW
B14: "30,100 sq ft" | D14: 150
B17: WHERE THE MONEY GOES
B18: Category | D18: Amount | E18: Share
B19: Build & Physical Production | D19: ='Production Budget'!F40+'Production Budget'!F210 -> 2505043.6 | E19: =D19/'Production Budget'!F263 -> 0.419903
B20: People (Fees + Salaries) | D20: ='Production Budget'!F90+'Production Budget'!F135+'Production Budget'!F150+'Production Budget'!F166 -> 1508698.5 | E20: =D20/'Production Budget'!F263 -> 0.25289261
B21: Marketing & Launch | D21: ='Production Budget'!F187 -> 754500 | E21: =D21/'Production Budget'!F263 -> 0.12647158
B22: G&A, Bonds, Reserve | D22: ='Production Budget'!F225+'Production Budget'!F233+'Production Budget'!F252+'Production Budget'!F261 -> 1197525.2 | E22: =D22/'Production Budget'!F263 -> 0.20073281
B23: TOTAL | D23: =SUM(D19:D22) -> 5965767.3 | E23: 1
B25: ="Breakeven at "&TEXT(Recoupment!C28,"0.0%")&" capacity · Recoup investor tier in "&TEXT('Production Budget'!F263*0.55/(('Seating Plan'!F28*0.9)-(('Weekly Operating'!F123-0.03*'Seating Plan'!F28)+0.03*0.9*'Seating Plan'!F28)),"0")&" weeks at 90% avg capacity" -> Breakeven at 64.1% capacity · Recoup investor tier in 80 weeks at 90% avg capacity
B27: 60-week run · 12 shows/week · Tiered pricing with community access on every performance

Sheet Summary
A1: NOT FOR DISTRIBUTION | F1: Brooklyn College THEA 7612X
A2: Get Lit Collective / If I Awaken Productions
A3: Los Angeles, CA | info@ifiawaken.com
A4: CONFIDENTIAL | F4: as of: 4/20/26
A6: IF I AWAKEN IN LOS ANGELES
A7: IMMERSIVE THEATRE · LOS ANGELES · BUDGET SUMMARY · v2 (no royalties)
A9: PRODUCTION COSTS (CAPITALIZATION)
B10: (100) PHYSICAL | C10: ='Production Budget'!F40 -> 2314250
B11: (200) FIXED FEES | C11: ='Production Budget'!F90 -> 1008879
B12: (300) SALARIES (Pre-Opening) | C12: ='Production Budget'!F135 -> 394919.48
B13: (400) CASTING / REHEARSAL EXPENSES | C13: ='Production Budget'!F150 -> 53500
B14: (500) MUSIC EXPENSES | C14: ='Production Budget'!F166 -> 51400
B15: (600) ADVERTISING & PROMOTION | C15: ='Production Budget'!F187 -> 754500
B16: (700) VENUE & TECH (Load-In) | C16: ='Production Budget'!F210 -> 190793.6
B17: (800) GENERAL & ADMINISTRATIVE | C17: ='Production Budget'!F225 -> 174700
B18: (900) DEVELOPMENTAL | C18: ='Production Budget'!F233 -> 75000
B19: SUBTOTAL PRODUCTION COSTS: | C19: ='Production Budget'!F235 -> 5017942.1
B21: (950) BONDS, DEPOSITS, ADVANCES | C21: ='Production Budget'!F252 -> 233500
B22: (1000) CONTINGENCY & RESERVE | C22: ='Production Budget'!F261 -> 714325.21
B23: TOTAL CAPITALIZATION: | C23: ='Production Budget'!F263 -> 5965767.3
A26: WEEKLY OPERATING COSTS (NO ROYALTIES)
B27: (1100) PHYSICAL MAINTENANCE | C27: ='Weekly Operating'!F23 -> 9300
B28: (1200) FEES (WEEKLY) | C28: ='Weekly Operating'!F39 -> 7900
B29: (1300) SALARIES (incl. Director + Writer) | C29: ='Weekly Operating'!F83 -> 67415.5
B30: (1400) ADVERTISING | C30: ='Weekly Operating'!F96 -> 10100
B31: (1500) VENUE & TECH | C31: ='Weekly Operating'!F109 -> 8400
B32: (1600) GENERAL & ADMIN | C32: ='Weekly Operating'!F121 -> 3150
B33: TOTAL WEEKLY OPERATING: | C33: ='Weekly Operating'!F123 -> 106265.5
A36: WEEKLY GROSS POTENTIAL & KEY METRICS
B37: Weekly Gross Potential (100%): | C37: ='Seating Plan'!F28 -> 163000
B38: Weekly Contribution (100% cap): | C38: ='Seating Plan'!F28-'Weekly Operating'!F123 -> 56734.5
B39: Weekly Contribution (80% cap est.): | C39: =('Seating Plan'!F28*0.8)-(('Weekly Operating'!F123-0.03*'Seating Plan'!F28)+0.03*0.8*'Seating Plan'!F28) -> 25112.5
B41: Breakeven Capacity: | C41: =Recoupment!C28 -> 0.6411707
B42: Weeks to Recoup @ 80% Capacity: | C42: =IF(('Seating Plan'!F28*0.8-(('Weekly Operating'!F123-0.03*'Seating Plan'!F28)+0.03*0.8*'Seating Plan'!F28))>0,'Production Budget'!F263/('Seating Plan'!F28*0.8-(('Weekly Operating'!F123-0.03*'Seating Plan'!F28)+0.03*0.8*'Seating Plan'!F28)),"—") -> 237.56166
A45: RECOMMENDED CAPITALIZATION STRUCTURE
B46: Source | C46: Amount | D46: % | E46: Notes
B47: Investor Capital (recoupable + profit share) | C47: =('Production Budget'!F263)*0.55 -> 3281172 | D47: 0.55 | E47: 120% recoupment + 50% profits post-recoup (despite no royalties, investors still get profit share).
B48: Institutional Grants (NEA, Mellon, LADF) | C48: =('Production Budget'!F263)*0.25 -> 1491441.8 | D48: 0.25 | E48: Mission-aligned arts funding — no recoupment obligation.
B49: Individual Philanthropy / Major Gifts | C49: =('Production Budget'!F263)*0.15 -> 894865.09 | D49: 0.15 | E49: Named sponsorships (spaces, programming) — no recoupment.
B50: Community / Earned (Kickstarter, memberships) | C50: =('Production Budget'!F263)*0.05 -> 298288.36 | D50: 0.05 | E50: Presale memberships + crowdfunding — community buy-in.
...

Sheet Assumptions
A1: NOT FOR DISTRIBUTION | F1: Brooklyn College THEA 7612X
A2: Get Lit Collective / If I Awaken Productions
A3: Los Angeles, CA | info@ifiawaken.com
A4: CONFIDENTIAL | F4: as of: 4/20/26
A6: ASSUMPTIONS
B8: Rehearsal Weeks | C8: 2 | E8: AEA (Actors + SMs) | F8: SMs only
B9: Tech Weeks | C9: 2 | E9: SDC (Director/Choreographer) | F9: Y
B10: Preview Weeks | C10: 2 | E10: USA (Designers) | F10: Y
B11: Performance Weeks (run) | C11: 60 | E11: AFM Local 47 (Musicians) | F11: Y
B12: Shows per week | C12: 12 | E12: ATPAM (House/Press) | F12: N
B13: Seat Capacity per show | C13: 150 | E13: Contract Type | F13: AEA SM contract
B14: Venue Size (sq ft) | C14: 30100 | E14: Stage Manager (PSM) | F14: 1
B15: Monthly Warehouse Rent | C15: 20000 | E15: Assistant Stage Managers | F15: 2
B16: Performers — Poets/Actors | C16: 9 | E16: Production Assistants | F16: 2
B17: of which AEA | C17: 0 | E17: Board Ops / LED Tech | F17: 2
B18: of which non-union | C18: 9 | E18: Sound / A1 | F18: 1
B19: Performers — Dancers (non-union) | C19: 5 | E19: Wardrobe Supv + Dressers | F19: 3
B20: Performers — Musicians (AFM) | C20: 5 | E20: Props Crew | F20: 1
B21: Understudies / Swings | C21: 4 | E21: Royalty Structure | F21: None
B22: Tour Guides / Wranglers per show | C22: 1
B25: Project Notes:
B26: • Immersive theatre across six themed environments in a 30,100 sq ft LA warehouse (long-term lease, buildout by production).
B27: • Journey: Lobby (bar, gift shop, box office) + Space 1 LED intro -> Space 2 Boyle Heights -> Space 3 Asian
B28: neighborhoods -> Space 4 African-American neighborhoods -> Space 5 Canyons/folk -> Space 6 Concert -> Space 1 reprise.
B29: • Scenic concept: miniature LA — forced-perspective iconic buildings + full-scale street props (e.g., taco stand).
B30: • Premium lighting design: lighting is a primary storytelling device, steering audience focus across 6 environments.
B31: • Performers double as tour guides where narratively appropriate; 3 dedicated wranglers per show.
B32: • Music composed by Derrick Hodge (Grammy); production owns composition rights — no composer fee, no royalty.
B33: • Compressed schedule: 2 rehearsal + 2 tech + 2 preview weeks (6 weeks pre-opening).
B34: • Run: 60 performance weeks, 12 shows/week (Thu–Sun).
B35: • Director: Andrew Scoville (Theater of the Mind, Here Lies Love Assoc., Money Heist: The Experience NYC).
B36: • General Manager: Mark Chinapen. | Producer: Gina.
... B38: • Partial AEA: 6 of 15 poets/actors + all 3 SMs AEA; dancers and remaining 9 poets non-union; musicians AFM Local 47.

Sheet Production Budget
A1: NOT FOR DISTRIBUTION | F1: Brooklyn College THEA 7612X
A2: Get Lit Collective / If I Awaken Productions
A3: Los Angeles, CA | info@ifiawaken.com
A4: CONFIDENTIAL | F4: as of: 4/20/26
A6: PRODUCTION BUDGET — IMMERSIVE (150 CAP, 30,100 SQ FT WAREHOUSE)
A7: Cast: 15 Poets/Actors | 5 Dancers | 5 Musicians | 4 Understudies/Swings
A9: (100) PHYSICAL
C10: units | D10: rate | E10: amount | F10: subtotal
A11: (101) | B11: Scenery — Spaces 2/3/4/5 (neighborhood builds) | E11: 750000
A12: (101a) | B12: Scenery — Space 1 (LED lobby/intro) | E12: 35000
A13: (101b) | B13: Scenery — Space 6 (concert stage + seating) | E13: 125000
A14: (101c) | B14: Lobby Bar — Build, Equipment, POS, Inventory | E14: 45000
A15: (101d) | B15: Lobby Gift Shop — Fixtures, Display, POS, Initial Inventory | E15: 20000
A16: (101e) | B16: Lobby Box Office — Counter, Ticketing Hardware, Display | E16: 12000
A17: (102) | B17: Automation / Moving Scenic Elements | E17: 25000
A18: (103) | B18: Costumes — Performers (25 total cast) | C18: 25 | D18: 2000 | E18: =C18*D18 -> 50000
A19: (104) | B19: Understudy Costumes | C19: 4 | D19: 2000 | E19: =C19*D19 -> 8000
A20: (104a) | B20: Wardrobe Perishables | E20: 4500
A21: (105) | B21: Costume Maintenance (pre-show) | E21: 3000
A22: (106) | B22: Electrics Purchase (premium install — 6 spaces) | E22: 200000
A23: (107) | B23: Electrics Rental (Tech) | E23: 22000
A24: (108) | B24: Sound Purchase (install — 6 spaces) | E24: 65000
A25: (109) | B25: Sound Rental (Tech) | E25: 15000
A26: (110) | B26: Props / Furniture (6 spaces) | E26: 140000
A27: (111) | B27: Special Effects (haze, fog, atmospherics) | E27: 15000
A28: (112) | B28: Projections Equipment (non-LED) | E28: 30000
A29: (113) | B29: LED Wall — Purchase (110 ft x 14 ft) | E29: 385000
A30: (113a) | B30: LED Media Servers / Playback Infrastructure | E30: 55000
A31: (113b) | B31: LED Content Creation / Video Production | E31: 75000
A32: (114) | B32: Hair / Wigs / Makeup | E32: 12000
A33: (115) | B33: Designer Expenses | C33: 9 | D33: 750 | E33: =C33*D33 -> 6750
A34: (116) | B34: Departmental Expenses / Hardware | E34: 8000
A35: (117) | B35: Carting / Trucking / Storage | E35: 18000
A36: (118) | B36: Venue Permitting & Occupancy Buildout | E36: 30000
A37: (119) | B37: Security Infrastructure (cameras, access, install, training) | E37: 85000
A38: (120) | B38: Exterior Wall Paint/Mural Wrap (front — ~3,820 sq ft) | E38: 75000
B40: TOTAL 100 — PHYSICAL | F40: =SUM(E11:E38) -> 2314250
A42: (200) FIXED FEES
C43: units | D43: rate | E43: amount | F43: subtotal
A44: (201) | B44: Author / Book Writer (includes 50% of run-period salary) | E44: 110000
...

Sheet Weekly Operating
A1: NOT FOR DISTRIBUTION | F1: Brooklyn College THEA 7612X
A2: Get Lit Collective / If I Awaken Productions
A3: Los Angeles, CA | info@ifiawaken.com
A4: CONFIDENTIAL | F4: as of: 4/20/26
A6: WEEKLY OPERATING BUDGET
A7: Per-week costs during 60-week run — NO ROYALTIES model (Director + Writer on salary)
A9: (1100) PHYSICAL MAINTENANCE
C10: units | D10: rate | E10: amount | F10: subtotal
A11: (1101) | B11: Costume Maintenance / Replacements | E11: 800
A12: (1102) | B12: Hair / Makeup Supplies | E12: 500
A13: (1103) | B13: Prop Replacements / Perishables | E13: 600
A14: (1104) | B14: Electrics Maintenance (premium lighting, 6 spaces) | E14: 800
A15: (1105) | B15: LED Wall Service Contract / Parts | E15: 1500
A16: (1106) | B16: Sound Maintenance / Batteries / Parts | E16: 400
A17: (1107) | B17: Scenic Repair / Paint / Hardware | E17: 600
A18: (1108) | B18: Cleaning / Janitorial (30K sqft) | E18: 2500
A19: (1109) | B19: Sanitation / Restroom Supplies | E19: 300
A20: (1110) | B20: Load-Out Accrual (weekly) | E20: 500
A21: (1111) | B21: Bar / Gift Shop — Restocking Allowance | E21: 800
B23: TOTAL 1100 — PHYSICAL MAINTENANCE | F23: =SUM(E11:E21) -> 9300
A25: (1200) FEES (WEEKLY)
C26: units | D26: rate | E26: amount | F26: subtotal
A27: (1201) | B27: General Management (50% — other 50% in prod budget) | E27: 1250
A28: (1202) | B28: Production Supervisor / Resident Director — ELIMINATED | E28: 0
A29: (1203) | B29: Music Director (weekly) — CUT | E29: 0
A30: (1204) | B30: Press Agent (weekly) | E30: 1500
A31: (1205) | B31: Advertising Agency (weekly) | E31: 1500
A32: (1206) | B32: Marketing / Social Media Agency | E32: 1500
A33: (1207) | B33: Casting Director (ongoing) — CUT | E33: 0
A34: (1208) | B34: Accounting / Bookkeeping (weekly) | E34: 1000
A35: (1209) | B35: Legal Retainer | E35: 400
A36: (1210) | B36: Payroll Service | E36: 250
A37: (1211) | B37: Property Manager (weekly) | E37: 500
B39: TOTAL 1200 — FEES | F39: =SUM(E27:E37) -> 7900
A41: (1300) SALARIES (WEEKLY)
C42: units | D42: rate | E42: amount | F42: subtotal
A43: (1300a) | B43: Director Scoville (50% — other 50% in prod budget) | C43: 1 | D43: 1250 | E43: =C43*D43 -> 1250
A44: (1300b) | B44: Writer / Author (50% — other 50% in prod budget) | C44: 1 | D44: 1250 | E44: =C44*D44 -> 1250
A45: (1301) | B45: Principals — AEA — ELIMINATED (cast now all non-union) | C45: 0 | D45: 1600 | E45: =C45*D45 -> 0
A46: (1301a) | B46: Principals — Non-union Poets (6) | C46: 6 | D46: 1400 | E46: =C46*D46 -> 8400
...

Sheet Seating Plan
A1: NOT FOR DISTRIBUTION | F1: Brooklyn College THEA 7612X
A2: Get Lit Collective / If I Awaken Productions
A3: Los Angeles, CA | info@ifiawaken.com
A4: CONFIDENTIAL | F4: as of: 4/20/26
A6: SEATING PLAN & GROSS POTENTIAL — TIERED WITHIN-SHOW PRICING
A7: 150-cap immersive · 12 shows/week · Every show has Community pricing
B9: Capacity per Show: | C9: 150
B10: Shows per Week: | C10: 12
B11: Weekly Capacity (seats): | C11: =C9*C10 -> 1800
A13: Day | B13: Tier | C13: Shows/Wk | D13: Seats/Show | E13: Price | F13: Weekly Gross
A14: Thursday — COMMUNITY NIGHT | B14: Community | C14: 2 | D14: 80 | E14: 40 | F14: =C14*D14*E14 -> 6400
B15: Standard | C15: 2 | D15: 50 | E15: 60 | F15: =C15*D15*E15 -> 6000
B16: Premium | C16: 2 | D16: 20 | E16: 80 | F16: =C16*D16*E16 -> 3200
A17: Friday | B17: Community | C17: 2 | D17: 40 | E17: 50 | F17: =C17*D17*E17 -> 4000
B18: Standard | C18: 2 | D18: 70 | E18: 80 | F18: =C18*D18*E18 -> 11200
B19: Premium | C19: 2 | D19: 40 | E19: 110 | F19: =C19*D19*E19 -> 8800
A20: Saturday — PEAK | B20: Community | C20: 4 | D20: 30 | E20: 60 | F20: =C20*D20*E20 -> 7200
B21: Standard | C21: 4 | D21: 50 | E21: 100 | F21: =C21*D21*E21 -> 20000
B22: Premium | C22: 4 | D22: 50 | E22: 140 | F22: =C22*D22*E22 -> 28000
B23: VIP (bar + shop voucher) | C23: 4 | D23: 20 | E23: 185 | F23: =C23*D23*E23 -> 14800
A24: Sunday | B24: Community | C24: 4 | D24: 40 | E24: 55 | F24: =C24*D24*E24 -> 8800
B25: Standard | C25: 4 | D25: 60 | E25: 90 | F25: =C25*D25*E25 -> 21600
B26: Premium | C26: 4 | D26: 50 | E26: 115 | F26: =C26*D26*E26 -> 23000
B28: WEEKLY GROSS POTENTIAL (100%): | F28: =SUM(F14:F26) -> 163000
B29: Weighted Average Ticket Price: | F29: =F28/C11 -> 90.555556
B31: Weekly Community Seats (accessible tier): | F31: =C14*D14+C17*D17+C20*D20+C24*D24 -> 520
B33: Capacity Scenarios:
B34: Capacity % | C34: Weekly Gross | D34: Tickets/Wk | E34: Avg Price
B35: 110% | C35: =F28*1.1 -> 179300 | D35: =C9*C10*1.1 -> 1980 | E35: =C35/D35 -> 90.555556
B36: 100% | C36: =F28*1 -> 163000 | D36: =C9*C10*1 -> 1800 | E36: =C36/D36 -> 90.555556
B37: 90% | C37: =F28*0.9 -> 146700 | D37: =C9*C10*0.9 -> 1620 | E37: =C37/D37 -> 90.555556
B38: 80% | C38: =F28*0.8 -> 130400 | D38: =C9*C10*0.8 -> 1440 | E38: =C38/D38 -> 90.555556
B39: 70% | C39: =F28*0.7 -> 114100 | D39: =C9*C10*0.7 -> 1260 | E39: =C39/D39 -> 90.555556
B40: 60% | C40: =F28*0.6 -> 97800 | D40: =C9*C10*0.6 -> 1080 | E40: =C40/D40 -> 90.555556
B41: 50% | C41: =F28*0.5 -> 81500 | D41: =C9*C10*0.5 -> 900 | E41: =C41/D41 -> 90.555556
B43: Pricing Philosophy:
B44: • Within-show tiered pricing: every performance has Community seats — accessibility is built into every show, not isolated to one night.
B45: • Community tier ($40-60) = accessible for students, LA neighborhood partners, Get Lit alumni, nonprofit coalitions.
B46: • Standard tier = market-rate ticket for general audience.
B47: • Premium tier = committed theatergoers / tourists / immersive enthusiasts.
...

Sheet Recoupment
A1: NOT FOR DISTRIBUTION | F1: Brooklyn College THEA 7612X
A2: Get Lit Collective / If I Awaken Productions
A3: Los Angeles, CA | info@ifiawaken.com
A4: CONFIDENTIAL | F4: as of: 4/20/26
A6: RECOUPMENT SCHEDULE
A7: Weeks to recoup capitalization — no-royalty model
B9: Total Capitalization: | C9: ='Production Budget'!F263 -> 5965767.3
B10: Weekly Operating Cost (at 100% GWBOR): | C10: ='Weekly Operating'!F123 -> 106265.5
B11: Weekly Gross Potential (100%): | C11: ='Seating Plan'!F28 -> 163000
B13: Capacity % | C13: Weekly GWBOR | D13: Weekly Op Cost | E13: Weekly Contribution | F13: Weeks to Recoup | G13: Months to Recoup
B14: 110% | C14: =C11*1.1 -> 179300 | D14: =(C10-0.03*C11)+0.03*C14 -> 106754.5 | E14: =C14-D14 -> 72545.5 | F14: =IF(E14>0,C9/E14,"—") -> 82.234836 | G14: =IF(E14>0,F14/4.33,"—") -> 18.991879
B15: 100% | C15: =C11*1 -> 163000 | D15: =(C10-0.03*C11)+0.03*C15 -> 106265.5 | E15: =C15-D15 -> 56734.5 | F15: =IF(E15>0,C9/E15,"—") -> 105.15237 | G15: =IF(E15>0,F15/4.33,"—") -> 24.284613
B16: 95% | C16: =C11*0.95 -> 154850 | D16: =(C10-0.03*C11)+0.03*C16 -> 106021 | E16: =C16-D16 -> 48829 | F16: =IF(E16>0,C9/E16,"—") -> 122.17672 | G16: =IF(E16>0,F16/4.33,"—") -> 28.216334
B17: 90% | C17: =C11*0.9 -> 146700 | D17: =(C10-0.03*C11)+0.03*C17 -> 105776.5 | E17: =C17-D17 -> 40923.5 | F17: =IF(E17>0,C9/E17,"—") -> 145.77852 | G17: =IF(E17>0,F17/4.33,"—") -> 33.667095
B18: 85% | C18: =C11*0.85 -> 138550 | D18: =(C10-0.03*C11)+0.03*C18 -> 105532 | E18: =C18-D18 -> 33018 | F18: =IF(E18>0,C9/E18,"—") -> 180.68227 | G18: =IF(E18>0,F18/4.33,"—") -> 41.728008
B19: 80% | C19: =C11*0.8 -> 130400 | D19: =(C10-0.03*C11)+0.03*C19 -> 105287.5 | E19: =C19-D19 -> 25112.5 | F19: =IF(E19>0,C9/E19,"—") -> 237.56166 | G19: =IF(E19>0,F19/4.33,"—") -> 54.864126
B20: 75% | C20: =C11*0.75 -> 122250 | D20: =(C10-0.03*C11)+0.03*C20 -> 105043 | E20: =C20-D20 -> 17207 | F20: =IF(E20>0,C9/E20,"—") -> 346.70583 | G20: =IF(E20>0,F20/4.33,"—") -> 80.070631
B21: 70% | C21: =C11*0.7 -> 114100 | D21: =(C10-0.03*C11)+0.03*C21 -> 104798.5 | E21: =C21-D21 -> 9301.5 | F21: =IF(E21>0,C9/E21,"—") -> 641.37691 | G21: =IF(E21>0,F21/4.33,"—") -> 148.124
B22: 65% | C22: =C11*0.65 -> 105950 | D22: =(C10-0.03*C11)+0.03*C22 -> 104554 | E22: =C22-D22 -> 1396 | F22: =IF(E22>0,C9/E22,"—") -> 4273.4723 | G22: =IF(E22>0,F22/4.33,"—") -> 986.9451
B23: 60% | C23: =C11*0.6 -> 97800 | D23: =(C10-0.03*C11)+0.03*C23 -> 104309.5 | E23: =C23-D23 -> -6509.5 | F23: =IF(E23>0,C9/E23,"—") -> — | G23: =IF(E23>0,F23/4.33,"—") -> —
B24: 55% | C24: =C11*0.55 -> 89650 | D24: =(C10-0.03*C11)+0.03*C24 -> 104065 | E24: =C24-D24 -> -14415 | F24: =IF(E24>0,C9/E24,"—") -> — | G24: =IF(E24>0,F24/4.33,"—") -> —
B25: 50% | C25: =C11*0.5 -> 81500 | D25: =(C10-0.03*C11)+0.03*C25 -> 103820.5 | E25: =C25-D25 -> -22320.5 | F25: =IF(E25>0,C9/E25,"—") -> — | G25: =IF(E25>0,F25/4.33,"—") -> —
B26: 45% | C26: =C11*0.45 -> 73350 | D26: =(C10-0.03*C11)+0.03*C26 -> 103576 | E26: =C26-D26 -> -30226 | F26: =IF(E26>0,C9/E26,"—") -> — | G26: =IF(E26>0,F26/4.33,"—") -> —
B28: BREAKEVEN CAPACITY: | C28: =((C10-0.03*C11)/(1-0.03))/C11 -> 0.6411707
B29: Breakeven Weekly GWBOR: | C29: =C28*C11 -> 104510.82
B30: Breakeven Avg Tickets / Show: | C30: =C28*150 -> 96.175606
B32: Notes:
B33: • Only ~3% of weekly op varies with capacity (CC fees). No royalties means far more fixed overhead.
B34: • NO ROYALTY model means breakeven is determined almost entirely by fixed weekly operating costs.
B35: • Show scheduled for 60-week run; any scenario requiring >60 weeks does not recoup within the run.
B36: • Does NOT include bar, gift shop, concessions revenue — these are real upside with expanded lobby.
B37: • Bar + gift shop could add 15-25% to gross revenue — conservative models add $15-30K/wk.
B38: • Without royalties, creative team has zero upside participation — may limit future revivals/licensing.
